Workbook

Sheet Aero Data
A1: Elevation (Wichita) | B1: 1300 ft
A3: Temperature
A4: R | B4: F
A5: 514.052 | B5: 54.382
A7: Density (slugs/ft3) | B7: 0.00228782
A8: Viscosity (slugs/ft*s) | B8: 3.710674e-07
A10: Speed of Sounds (ft/s)
A11: =SQRT(1.4*1716*A5) -> 1111.2869
A13: Airfoil: | B13: NACA4418 | M13: Cruise | O13: Take Off (α=8)
A14: Re #: | B14: 250000 | E14: CL Max | F14: =MAX('Wing Chract. (Ref)'!J7:J20) -> 1.0055854 | J14: V (ft/s) | K14: V(mph) | L14: Mach # | M14: Lift | N14: Drag | O14: Lift | P14: Drag
A15: t/c | B15: 0.18 | E15: CL α=0 | F15: ='Wing Chract. (Ref)'!J14 -> 0.27791688 | J15: 25 | K15: 17.045455 | L15: 0.022496441 | M15: =0.5*'Wing Info. (Ref)'!$I$2*'Wing Info. (Ref)'!$B$4*'Wing Chract. (Ref)'!$J$14*('Aero Data'!J15)^2 -> 1.0288424 | N15: =0.5*'Wing Info. (Ref)'!$I$2*'Wing Info. (Ref)'!$B$4*'Wing Chract. (Ref)'!$K$14*(J15)^2 -> 0.070160998 | O15: =0.5*'Wing Info. (Ref)'!$I$2*'Wing Info. (Ref)'!$B$4*'Wing Chract. (Ref)'!$J$10*('Aero Data'!J15)^2 -> 2.937041 | P15: =0.5*'Wing Info. (Ref)'!$I$2*'Wing Info. (Ref)'!$B$4*'Wing Chract. (Ref)'!$K$10*('Aero Data'!J15)^2 -> 0.24766188
A16: Wing Span (ft) | B16: ='Wing Info. (Ref)'!E3 -> 4.5 | E16: αCl=0 (deg) | F16: =('Wing Chract. (Ref)'!A16)-(('Wing Chract. (Ref)'!B16)/(('Wing Chract. (Ref)'!B16-'Wing Chract. (Ref)'!B17)/('Wing Chract. (Ref)'!A16-'Wing Chract. (Ref)'!A17))) -> -4.3133554 | J16: 30 | K16: 20.454546 | L16: 0.02699573 | M16: =0.5*'Wing Info. (Ref)'!$I$2*'Wing Info. (Ref)'!$B$4*'Wing Chract. (Ref)'!$J$14*('Aero Data'!J16)^2 -> 1.481533 | N16: =0.5*'Wing Info. (Ref)'!$I$2*'Wing Info. (Ref)'!$B$4*'Wing Chract. (Ref)'!$K$14*(J16)^2 -> 0.10103184 | O16: =0.5*'Wing Info. (Ref)'!$I$2*'Wing Info. (Ref)'!$B$4*'Wing Chract. (Ref)'!$J$10*('Aero Data'!J16)^2 -> 4.2293391 | P16: =0.5*'Wing Info. (Ref)'!$I$2*'Wing Info. (Ref)'!$B$4*'Wing Chract. (Ref)'!$K$10*('Aero Data'!J16)^2 -> 0.35663311
A17: Estimated Weight (lb) | B17: ='Wing Info. (Ref)'!E1 -> 8 | E17: CD0 | F17: ='Wing Chract. (Ref)'!K14 -> 0.018952296 | J17: 35 | K17: 23.863637 | L17: 0.031495018 | M17: =0.5*'Wing Info. (Ref)'!$I$2*'Wing Info. (Ref)'!$B$4*'Wing Chract. (Ref)'!$J$14*('Aero Data'!J17)^2 -> 2.016531 | N17: =0.5*'Wing Info. (Ref)'!$I$2*'Wing Info. (Ref)'!$B$4*'Wing Chract. (Ref)'!$K$14*(J17)^2 -> 0.13751556 | O17: =0.5*'Wing Info. (Ref)'!$I$2*'Wing Info. (Ref)'!$B$4*'Wing Chract. (Ref)'!$J$10*('Aero Data'!J17)^2 -> 5.7566004 | P17: =0.5*'Wing Info. (Ref)'!$I$2*'Wing Info. (Ref)'!$B$4*'Wing Chract. (Ref)'!$K$10*('Aero Data'!J17)^2 -> 0.48541728
A18: e | B18: ='Wing Info. (Ref)'!E6 -> 0.97786449 | E18: Cm0 | F18: ='Wing Chract. (Ref)'!E14 -> -0.0962 | J18: 40 | K18: 27.272728 | L18: 0.035994306 | M18: =0.5*'Wing Info. (Ref)'!$I$2*'Wing Info. (Ref)'!$B$4*'Wing Chract. (Ref)'!$J$14*('Aero Data'!J18)^2 -> 2.6338365 | N18: =0.5*'Wing Info. (Ref)'!$I$2*'Wing Info. (Ref)'!$B$4*'Wing Chract. (Ref)'!$K$14*(J18)^2 -> 0.17961215 | O18: =0.5*'Wing Info. (Ref)'!$I$2*'Wing Info. (Ref)'!$B$4*'Wing Chract. (Ref)'!$J$10*('Aero Data'!J18)^2 -> 7.518825 | P18: =0.5*'Wing Info. (Ref)'!$I$2*'Wing Info. (Ref)'!$B$4*'Wing Chract. (Ref)'!$K$10*('Aero Data'!J18)^2 -> 0.63401441
A19: AR | B19: ='Wing Info. (Ref)'!F11 -> 3.9107764 | E19: Cmα (/deg) | F19: =('Wing Chract. (Ref)'!E12-'Wing Chract. (Ref)'!E17)/('Wing Chract. (Ref)'!A12-'Wing Chract. (Ref)'!A17) -> 0.00055 | G19: =F19*180/PI() -> 0.031512679 | H19: Cmα (/rad) | J19: 45 | K19: 30.681819 | L19: 0.040493594 | M19: =0.5*'Wing Info. (Ref)'!$I$2*'Wing Info. (Ref)'!$B$4*'Wing Chract. (Ref)'!$J$14*('Aero Data'!J19)^2 -> 3.3334493 | N19: =0.5*'Wing Info. (Ref)'!$I$2*'Wing Info. (Ref)'!$B$4*'Wing Chract. (Ref)'!$K$14*(J19)^2 -> 0.22732163 | O19: =0.5*'Wing Info. (Ref)'!$I$2*'Wing Info. (Ref)'!$B$4*'Wing Chract. (Ref)'!$J$10*('Aero Data'!J19)^2 -> 9.5160129 | P19: =0.5*'Wing Info. (Ref)'!$I$2*'Wing Info. (Ref)'!$B$4*'Wing Chract. (Ref)'!$K$10*('Aero Data'!J19)^2 -> 0.80242449
J20: 50 | K20: 34.09091 | L20: 0.044992883 | M20: =0.5*'Wing Info. (Ref)'!$I$2*'Wing Info. (Ref)'!$B$4*'Wing Chract. (Ref)'!$J$14*('Aero Data'!J20)^2 -> 4.1153695 | N20: =0.5*'Wing Info. (Ref)'!$I$2*'Wing Info. (Ref)'!$B$4*'Wing Chract. (Ref)'!$K$14*(J20)^2 -> 0.28064399 | O20: =0.5*'Wing Info. (Ref)'!$I$2*'Wing Info. (Ref)'!$B$4*'Wing Chract. (Ref)'!$J$10*('Aero Data'!J20)^2 -> 11.748164 | P20: =0.5*'Wing Info. (Ref)'!$I$2*'Wing Info. (Ref)'!$B$4*'Wing Chract. (Ref)'!$K$10*('Aero Data'!J20)^2 -> 0.99064752
A21: xac (%) | B21: ='Wing Info. (Ref)'!G11 -> 24.46868 | E21: αtake off (deg) | F21: 8 | J21: 55 | K21: 37.500001 | L21: 0.049492171 | M21: =0.5*'Wing Info. (Ref)'!$I$2*'Wing Info. (Ref)'!$B$4*'Wing Chract. (Ref)'!$J$14*('Aero Data'!J21)^2 -> 4.9795971 | N21: =0.5*'Wing Info. (Ref)'!$I$2*'Wing Info. (Ref)'!$B$4*'Wing Chract. (Ref)'!$K$14*(J21)^2 -> 0.33957923 | O21: =0.5*'Wing Info. (Ref)'!$I$2*'Wing Info. (Ref)'!$B$4*'Wing Chract. (Ref)'!$J$10*('Aero Data'!J21)^2 -> 14.215279 | P21: =0.5*'Wing Info. (Ref)'!$I$2*'Wing Info. (Ref)'!$B$4*'Wing Chract. (Ref)'!$K$10*('Aero Data'!J21)^2 -> 1.1986835
J22: 60 | K22: 40.909092 | L22: 0.053991459 | M22: =0.5*'Wing Info. (Ref)'!$I$2*'Wing Info. (Ref)'!$B$4*'Wing Chract. (Ref)'!$J$14*('Aero Data'!J22)^2 -> 5.926132 | N22: =0.5*'Wing Info. (Ref)'!$I$2*'Wing Info. (Ref)'!$B$4*'Wing Chract. (Ref)'!$K$14*(J22)^2 -> 0.40412735 | O22: =0.5*'Wing Info. (Ref)'!$I$2*'Wing Info. (Ref)'!$B$4*'Wing Chract. (Ref)'!$J$10*('Aero Data'!J22)^2 -> 16.917356 | P22: =0.5*'Wing Info. (Ref)'!$I$2*'Wing Info. (Ref)'!$B$4*'Wing Chract. (Ref)'!$K$10*('Aero Data'!J22)^2 -> 1.4265324
B23: Root | C23: Tip | F23: fps | G23: mph | J23: 65 | K23: 44.318183 | L23: 0.058490747 | M23: =0.5*'Wing Info. (Ref)'!$I$2*'Wing Info. (Ref)'!$B$4*'Wing Chract. (Ref)'!$J$14*('Aero Data'!J23)^2 -> 6.9549744 | N23: =0.5*'Wing Info. (Ref)'!$I$2*'Wing Info. (Ref)'!$B$4*'Wing Chract. (Ref)'!$K$14*(J23)^2 -> 0.47428834 | O23: =0.5*'Wing Info. (Ref)'!$I$2*'Wing Info. (Ref)'!$B$4*'Wing Chract. (Ref)'!$J$10*('Aero Data'!J23)^2 -> 19.854397 | P23: =0.5*'Wing Info. (Ref)'!$I$2*'Wing Info. (Ref)'!$B$4*'Wing Chract. (Ref)'!$K$10*('Aero Data'!J23)^2 -> 1.6741943
A24: Chord (in) | B24: 24 | C24: 6 | E24: Vstall | F24: =SQRT((2*$B$17)/($B$7*$C$28*'Wing Chract. (Ref)'!J7)) -> 36.648699 | G24: =F24*0.6828283 -> 25.024769 | J24: 70 | K24: 47.727274 | L24: 0.062990036 | M24: =0.5*'Wing Info. (Ref)'!$I$2*'Wing Info. (Ref)'!$B$4*'Wing Chract. (Ref)'!$J$14*('Aero Data'!J24)^2 -> 8.0661242 | N24: =0.5*'Wing Info. (Ref)'!$I$2*'Wing Info. (Ref)'!$B$4*'Wing Chract. (Ref)'!$K$14*(J24)^2 -> 0.55006222 | O24: =0.5*'Wing Info. (Ref)'!$I$2*'Wing Info. (Ref)'!$B$4*'Wing Chract. (Ref)'!$J$10*('Aero Data'!J24)^2 -> 23.026402 | P24: =0.5*'Wing Info. (Ref)'!$I$2*'Wing Info. (Ref)'!$B$4*'Wing Chract. (Ref)'!$K$10*('Aero Data'!J24)^2 -> 1.9416691
A25: Thickness (in) | B25: =B24*B15 -> 4.32 | C25: =C24*B15 -> 1.08 | E25: Vcruise | F25: =SQRT((2*$B$17)/($B$7*$C$28*'Wing Chract. (Ref)'!$J$14)) -> 69.712488 | G25: =F25*0.6828283 -> 47.60166 | J25: 75 | K25: 51.136365 | L25: 0.067489324 | M25: =0.5*'Wing Info. (Ref)'!$I$2*'Wing Info. (Ref)'!$B$4*'Wing Chract. (Ref)'!$J$14*('Aero Data'!J25)^2 -> 9.2595813 | N25: =0.5*'Wing Info. (Ref)'!$I$2*'Wing Info. (Ref)'!$B$4*'Wing Chract. (Ref)'!$K$14*(J25)^2 -> 0.63144898 | O25: =0.5*'Wing Info. (Ref)'!$I$2*'Wing Info. (Ref)'!$B$4*'Wing Chract. (Ref)'!$J$10*('Aero Data'!J25)^2 -> 26.433369 | P25: =0.5*'Wing Info. (Ref)'!$I$2*'Wing Info. (Ref)'!$B$4*'Wing Chract. (Ref)'!$K$10*('Aero Data'!J25)^2 -> 2.2289569
E26: Vtake off | F26: =SQRT((2*$B$17)/($B$7*$C$28*'Wing Chract. (Ref)'!$J$10)) -> 41.260073 | G26: =F26*0.6828283 -> 28.173546 | J26: 80 | K26: 54.545456 | L26: 0.071988612 | M26: =0.5*'Wing Info. (Ref)'!$I$2*'Wing Info. (Ref)'!$B$4*'Wing Chract. (Ref)'!$J$14*('Aero Data'!J26)^2 -> 10.535346 | N26: =0.5*'Wing Info. (Ref)'!$I$2*'Wing Info. (Ref)'!$B$4*'Wing Chract. (Ref)'!$K$14*(J26)^2 -> 0.71844862 | O26: =0.5*'Wing Info. (Ref)'!$I$2*'Wing Info. (Ref)'!$B$4*'Wing Chract. (Ref)'!$J$10*('Aero Data'!J26)^2 -> 30.0753 | P26: =0.5*'Wing Info. (Ref)'!$I$2*'Wing Info. (Ref)'!$B$4*'Wing Chract. (Ref)'!$K$10*('Aero Data'!J26)^2 -> 2.5360577
B27: in2 | C27: ft2 | J27: 85 | K27: 57.954547 | L27: 0.0764879 | M27: =0.5*'Wing Info. (Ref)'!$I$2*'Wing Info. (Ref)'!$B$4*'Wing Chract. (Ref)'!$J$14*('Aero Data'!J27)^2 -> 11.893418 | N27: =0.5*'Wing Info. (Ref)'!$I$2*'Wing Info. (Ref)'!$B$4*'Wing Chract. (Ref)'!$K$14*(J27)^2 -> 0.81106113 | O27: =0.5*'Wing Info. (Ref)'!$I$2*'Wing Info. (Ref)'!$B$4*'Wing Chract. (Ref)'!$J$10*('Aero Data'!J27)^2 -> 33.952194 | P27: =0.5*'Wing Info. (Ref)'!$I$2*'Wing Info. (Ref)'!$B$4*'Wing Chract. (Ref)'!$K$10*('Aero Data'!J27)^2 -> 2.8629713
A28: Surface Area | B28: 745.632 | C28: =B28/144 -> 5.178 | J28: 90 | K28: 61.363638 | L28: 0.080987189 | M28: =0.5*'Wing Info. (Ref)'!$I$2*'Wing Info. (Ref)'!$B$4*'Wing Chract. (Ref)'!$J$14*('Aero Data'!J28)^2 -> 13.333797 | N28: =0.5*'Wing Info. (Ref)'!$I$2*'Wing Info. (Ref)'!$B$4*'Wing Chract. (Ref)'!$K$14*(J28)^2 -> 0.90928653 | O28: =0.5*'Wing Info. (Ref)'!$I$2*'Wing Info. (Ref)'!$B$4*'Wing Chract. (Ref)'!$J$10*('Aero Data'!J28)^2 -> 38.064052 | P28: =0.5*'Wing Info. (Ref)'!$I$2*'Wing Info. (Ref)'!$B$4*'Wing Chract. (Ref)'!$K$10*('Aero Data'!J28)^2 -> 3.209698
J29: 95 | K29: 64.772729 | L29: 0.085486477 | M29: =0.5*'Wing Info. (Ref)'!$I$2*'Wing Info. (Ref)'!$B$4*'Wing Chract. (Ref)'!$J$14*('Aero Data'!J29)^2 -> 14.856484 | N29: =0.5*'Wing Info. (Ref)'!$I$2*'Wing Info. (Ref)'!$B$4*'Wing Chract. (Ref)'!$K$14*(J29)^2 -> 1.0131248 | O29: =0.5*'Wing Info. (Ref)'!$I$2*'Wing Info. (Ref)'!$B$4*'Wing Chract. (Ref)'!$J$10*('Aero Data'!J29)^2 -> 42.410873 | P29: =0.5*'Wing Info. (Ref)'!$I$2*'Wing Info. (Ref)'!$B$4*'Wing Chract. (Ref)'!$K$10*('Aero Data'!J29)^2 -> 3.5762375
B30: deg | C30: rad | J30: 100 | K30: 68.18182 | L30: 0.089985765 | M30: =0.5*'Wing Info. (Ref)'!$I$2*'Wing Info. (Ref)'!$B$4*'Wing Chract. (Ref)'!$J$14*('Aero Data'!J30)^2 -> 16.461478 | N30: =0.5*'Wing Info. (Ref)'!$I$2*'Wing Info. (Ref)'!$B$4*'Wing Chract. (Ref)'!$K$14*(J30)^2 -> 1.122576 | O30: =0.5*'Wing Info. (Ref)'!$I$2*'Wing Info. (Ref)'!$B$4*'Wing Chract. (Ref)'!$J$10*('Aero Data'!J30)^2 -> 46.992657 | P30: =0.5*'Wing Info. (Ref)'!$I$2*'Wing Info. (Ref)'!$B$4*'Wing Chract. (Ref)'!$K$10*('Aero Data'!J30)^2 -> 3.9625901
A31: Sweep Angle 0.5c | B31: 9.827 | C31: =B31*PI()/180 -> 0.17151351 | J31: 105 | K31: 71.590911 | L31: 0.094485053 | M31: =0.5*'Wing Info. (Ref)'!$I$2*'Wing Info. (Ref)'!$B$4*'Wing Chract. (Ref)'!$J$14*('Aero Data'!J31)^2 -> 18.148779 | N31: =0.5*'Wing Info. (Ref)'!$I$2*'Wing Info. (Ref)'!$B$4*'Wing Chract. (Ref)'!$K$14*(J31)^2 -> 1.23764 | O31: =0.5*'Wing Info. (Ref)'!$I$2*'Wing Info. (Ref)'!$B$4*'Wing Chract. (Ref)'!$J$10*('Aero Data'!J31)^2 -> 51.809404 | P31: =0.5*'Wing Info. (Ref)'!$I$2*'Wing Info. (Ref)'!$B$4*'Wing Chract. (Ref)'!$K$10*('Aero Data'!J31)^2 -> 4.3687556
A32: Sweep Angle LE | B32: 9.096 | C32: =B32*PI()/180 -> 0.15875515 | J32: 110 | K32: 75.000002 | L32: 0.098984342 | M32: =0.5*'Wing Info. (Ref)'!$I$2*'Wing Info. (Ref)'!$B$4*'Wing Chract. (Ref)'!$J$14*('Aero Data'!J32)^2 -> 19.918388 | N32: =0.5*'Wing Info. (Ref)'!$I$2*'Wing Info. (Ref)'!$B$4*'Wing Chract. (Ref)'!$K$14*(J32)^2 -> 1.3583169 | O32: =0.5*'Wing Info. (Ref)'!$I$2*'Wing Info. (Ref)'!$B$4*'Wing Chract. (Ref)'!$J$10*('Aero Data'!J32)^2 -> 56.861114 | P32: =0.5*'Wing Info. (Ref)'!$I$2*'Wing Info. (Ref)'!$B$4*'Wing Chract. (Ref)'!$K$10*('Aero Data'!J32)^2 -> 4.794734
A34: Taper Ratio | B34: =C24/B24 -> 0.25
A35: Mean Aerodynamic Chord | B35: =(2/3)*B24*(1+B34+B34^2)/(1+B34) -> 16.8
A36: Y bar | B36: =(12*B16/6)*((1+2*B34)/(1+B34)) -> 10.8

Sheet Wing Info. (Ref)
A1: Airfoil: | B1: NACA4418 | D1: Desired Weight (lb): | E1: 8 | H1: in2 | I1: ft2 | K1: Taper Ratio | L1: Mean Aerodynamic Chord | M1: Y bar
A2: Re #: | B2: 250000 | D2: Desired Vcruise (ft/s): | E2: 33.34 | G2: Surface Area | H2: 745.632 | I2: =H2/144 -> 5.178 | K2: =C7/B7 -> 0.25 | L2: =(2/3)*B7*(1+K2+K2^2)/(1+K2) -> 16.8 | M2: =(12*E3/6)*((1+2*K2)/(1+K2)) -> 10.8
A3: t/c | B3: 0.18 | D3: Desired Wing Span (ft): | E3: 4.5
A4: Density (slug/ft3): | B4: 0.00228782 | G4: αCl=0 | H4: a0 (0-8) | J4: a (0-8) | M4: m0
E5: e | G5: deg | H5: /deg | I5: /rad | J5: /deg | K5: /rad | M5: /deg | N5: /rad
B6: Root | C6: Tip | E6: =4.61*(1-0.045*F11^(0.68))*(COS(C12))^0.15-3.1 -> 0.97786449 | G6: =('Wing Chract. (Ref)'!A16)-(('Wing Chract. (Ref)'!B16)/(('Wing Chract. (Ref)'!B16-'Wing Chract. (Ref)'!B17)/('Wing Chract. (Ref)'!A16-'Wing Chract. (Ref)'!A17))) -> -4.3133554 | H6: =('Wing Chract. (Ref)'!B14-0)/(0-'Wing Info. (Ref)'!G6) -> 0.1035157 | I6: =H6*180/PI() -> 5.9310127 | J6: =K6*PI()/180 -> 0.064431713 | K6: =I6*COS(C11)/(SQRT(1+(I6*COS(C11)/(PI()*F11))^2)+(I6*COS(C11)/(PI()*F11))) -> 3.6916652 | M6: =('Wing Chract. (Ref)'!E12-'Wing Chract. (Ref)'!E17)/('Wing Chract. (Ref)'!A12-'Wing Chract. (Ref)'!A17) -> 0.00055 | N6: =M6*180/PI() -> 0.031512679
A7: Chord | B7: 24 | C7: 6 | H7: =('Wing Chract. (Ref)'!B8-'Wing Chract. (Ref)'!B9)/('Wing Chract. (Ref)'!A8-'Wing Chract. (Ref)'!A9) -> 0.04385 | I7: =H7*180/PI() -> 2.5124199 | J7: =K7*PI()/180 -> 0.035369139 | K7: =I7*COS(C11)/(SQRT(1+(I7*COS(C11)/(PI()*F11))^2)+(I7*COS(C11)/(PI()*F11))) -> 2.0265024
A8: Thickness | B8: =B7*B3 -> 4.32 | C8: =C7*B3 -> 1.08 | H8: a0 (8-16) | J8: a (8-16)
B10: deg | C10: rad | F10: Aspect Ratio | G10: xac (%) | H10: Vstall (ft/s) | I10: Vcruise (ft/s) | J10: Lift takeoff (lb) | K10: Lift cruise (lb) | L10: Lift Cruise Desired V (lb)
A11: Sweep Angle 0.5c | B11: -9.827 | C11: =B11*PI()/180 -> -0.17151351 | E11: 2D | F11: =E3^2/I2 -> 3.9107764 | G11: =((-M6/H6)+0.25)*100 -> 24.46868 | H11: =SQRT((2*$E$1)/($B$4*$I$2*'Wing Chract. (Ref)'!B9)) -> 31.034702 | I11: =SQRT((2*$E$1)/($B$4*$I$2*'Wing Chract. (Ref)'!$B$14)) -> 54.999319 | J11: =0.5*'Wing Chract. (Ref)'!B9*$I$2*$B$4*$H$11^2 -> 8 | K11: =0.5*'Wing Chract. (Ref)'!$B$14*$I$2*$B$4*$I$11^2 -> 8 | L11: =0.5*'Wing Chract. (Ref)'!$B$14*$I$2*$B$4*$E$2^2 -> 2.939724
A12: Sweep Angle LE | B12: 9.096 | C12: =B12*PI()/180 -> 0.15875515 | E12: 3D | H12: =SQRT((2*$E$1)/($B$4*$I$2*'Wing Chract. (Ref)'!J7)) -> 36.648699 | I12: =SQRT((2*$E$1)/($B$4*$I$2*'Wing Chract. (Ref)'!$J$14)) -> 69.712488 | J12: =0.5*'Wing Chract. (Ref)'!J7*$I$2*$B$4*$H$12^2 -> 8 | K12: =0.5*'Wing Chract. (Ref)'!$J$14*$I$2*$B$4*$I$12^2 -> 8 | L12: =0.5*'Wing Chract. (Ref)'!$J$14*$I$2*$B$4*$E$2^2 -> 1.8297848

Sheet Wing Chract. (Ref)
O1: t/w | P1: T/W
A2: alpha | B2: Cl | C2: Cd | D2: Cdp | E2: Cm | F2: Top_Xtr | G2: Bot_Xtr | I2: Linealized Cl | J2: CL | K2: CD | L2: CM | M2: l/d | N2: L/D | O2: 1/(l/d) | P2: 1/(L/D)
A3: ------ | B3: -------- | C3: --------- | D3: --------- | E3: -------- | F3: -------- | G3: -------- | I3: -------- | J3: -------- | K3: -------- | L3: -------- | M3: -------- | N3: -------- | O3: -------- | P3: --------
A4: 20 | B4: 1.4505 | C4: 0.11449 | D4: 0.10857 | E4: -0.0358 | F4: 0.0921 | G4: 1 | M4: =B4/C4 -> 12.669229 | O4: =1/M4 -> 0.078931403
A5: 18 | B5: 1.4718 | C5: 0.08707 | D5: 0.08089 | E5: -0.0309 | F5: 0.1228 | G5: 1 | M5: =B5/C5 -> 16.903641 | O5: =1/M5 -> 0.059158853
A6: 16 | B6: 1.5117 | C6: 0.0591 | D6: 0.05272 | E6: -0.0308 | F6: 0.17 | G6: 1 | M6: =B6/C6 -> 25.57868 | O6: =1/M6 -> 0.039095059 | S6: cl | T6: cl2/piar | U6: cd
A7: 14 | B7: 1.5266 | C7: 0.03774 | D7: 0.03114 | E7: -0.0379 | F7: 0.235 | G7: 1 | I7: ='Wing Info. (Ref)'!$H$7*('Wing Chract. (Ref)'!A7-$A$10)+$I$26 -> 1.5377256 | J7: ='Wing Info. (Ref)'!$J$7*('Wing Chract. (Ref)'!A7-$A$10)+$J$26 -> 1.0055854 | K7: 0.10563604 | M7: =B7/C7 -> 40.45045 | N7: =J7/K7 -> 9.51934 | O7: =1/M7 -> 0.024721604 | P7: =1/N7 -> 0.1050493 | S7: =0.1035*((A7-((57.3*J7)/(PI()*3.6)))-(-4.313)) -> 1.3680909 | T7: =J7^2/(PI()*'Wing Info. (Ref)'!$F$11*'Wing Info. (Ref)'!$E$6) -> 0.084167884 | U7: 0.019958 | V7: =T7+U7 -> 0.10412588
A8: 12 | B8: 1.49 | C8: 0.02577 | D8: 0.01906 | E8: -0.052 | F8: 0.3051 | G8: 1 | I8: ='Wing Info. (Ref)'!$H$7*('Wing Chract. (Ref)'!A8-$A$10)+$I$26 -> 1.4500256 | J8: ='Wing Info. (Ref)'!$J$7*('Wing Chract. (Ref)'!A8-$A$10)+$J$26 -> 0.93484714 | K8: 0.09051754 | M8: =B8/C8 -> 57.81917 | N8: =J8/K8 -> 10.327801 | O8: =1/M8 -> 0.017295302 | P8: =1/N8 -> 0.096826033 | S8: =0.1035*((A8-((57.3*J8)/(PI()*3.6)))-(-4.313)) -> 1.1981843 | T8: =J8^2/(PI()*'Wing Info. (Ref)'!$F$11*'Wing Info. (Ref)'!$E$6) -> 0.072742744 | U8: 0.01638 | V8: =T8+U8 -> 0.089122744
A9: 10 | B9: 1.4023 | C9: 0.02013 | D9: 0.01323 | E9: -0.0686 | F9: 0.3699 | G9: 1 | I9: ='Wing Info. (Ref)'!$H$7*('Wing Chract. (Ref)'!A9-$A$10)+$I$26 -> 1.3623256 | J9: ='Wing Info. (Ref)'!$J$7*('Wing Chract. (Ref)'!A9-$A$10)+$J$26 -> 0.86410886 | K9: 0.07803148 | M9: =B9/C9 -> 69.662196 | N9: =J9/K9 -> 11.073849 | O9: =1/M9 -> 0.014354988 | P9: =1/N9 -> 0.090302835 | S9: =0.1035*((A9-((57.3*J9)/(PI()*3.6)))-(-4.313)) -> 1.0282778 | T9: =J9^2/(PI()*'Wing Info. (Ref)'!$F$11*'Wing Info. (Ref)'!$E$6) -> 0.062150609 | U9: 0.0146 | V9: =T9+U9 -> 0.076750609
A10: 8 | B10: 1.2779 | C10: 0.01748 | D10: 0.01046 | E10: -0.0847 | F10: 0.4251 | G10: 1 | I10: ='Wing Info. (Ref)'!$H$6*('Wing Chract. (Ref)'!A10-'Wing Info. (Ref)'!$G$6) -> 1.2746256 | J10: ='Wing Info. (Ref)'!$J$6*('Wing Chract. (Ref)'!A10-'Wing Info. (Ref)'!$G$6) -> 0.79337058 | K10: 0.066899866 | M10: =B10/C10 -> 73.106407 | N10: =J10/K10 -> 11.859076 | O10: =1/M10 -> 0.013678692 | P10: =1/N10 -> 0.084323602 | S10: =0.1035*((A10-((57.3*J10)/(PI()*3.6)))-(-4.313)) -> 0.85837121 | T10: =J10^2/(PI()*'Wing Info. (Ref)'!$F$11*'Wing Info. (Ref)'!$E$6) -> 0.052391479 | U10: 0.01334 | V10: =T10+U10 -> 0.065731479
A11: 6 | B11: 1.1107 | C11: 0.01556 | D11: 0.00844 | E11: -0.0946 | F11: 0.4746 | G11: 1 | I11: ='Wing Info. (Ref)'!$H$6*('Wing Chract. (Ref)'!A11-'Wing Info. (Ref)'!$G$6) -> 1.0675942 | J11: ='Wing Info. (Ref)'!$J$6*('Wing Chract. (Ref)'!A11-'Wing Info. (Ref)'!$G$6) -> 0.66450716 | K11: 0.05017393 | M11: =B11/C11 -> 71.381748 | N11: =J11/K11 -> 13.244072 | O11: =1/M11 -> 0.014009183 | P11: =1/N11 -> 0.075505476 | S11: =0.1035*((A11-((57.3*J11)/(PI()*3.6)))-(-4.313)) -> 0.71894406 | T11: =J11^2/(PI()*'Wing Info. (Ref)'!$F$11*'Wing Info. (Ref)'!$E$6) -> 0.03675427 | U11: 0.0126 | V11: =T11+U11 -> 0.04935427
A12: 4 | B12: 0.9309 | C12: 0.01381 | D12: 0.00699 | E12: -0.1026 | F12: 0.5205 | G12: 1 | I12: ='Wing Info. (Ref)'!$H$6*('Wing Chract. (Ref)'!A12-'Wing Info. (Ref)'!$G$6) -> 0.8605628 | J12: ='Wing Info. (Ref)'!$J$6*('Wing Chract. (Ref)'!A12-'Wing Info. (Ref)'!$G$6) -> 0.53564373 | K12: 0.036514023 | M12: =B12/C12 -> 67.407676 | N12: =J12/K12 -> 14.669535 | O12: =1/M12 -> 0.014835106 | P12: =1/N12 -> 0.068168487 | S12: =0.1035*((A12-((57.3*J12)/(PI()*3.6)))-(-4.313)) -> 0.57951692 | T12: =J12^2/(PI()*'Wing Info. (Ref)'!$F$11*'Wing Info. (Ref)'!$E$6) -> 0.023881441 | U12: 0.0121 | V12: =T12+U12 -> 0.035981441
A13: 2 | B13: 0.7057 | C13: 0.01258 | D13: 0.00614 | E13: -0.1005 | F13: 0.5721 | G13: 0.9798 | I13: ='Wing Info. (Ref)'!$H$6*('Wing Chract. (Ref)'!A13-'Wing Info. (Ref)'!$G$6) -> 0.6535314 | J13: ='Wing Info. (Ref)'!$J$6*('Wing Chract. (Ref)'!A13-'Wing Info. (Ref)'!$G$6) -> 0.4067803 | K13: 0.025080145 | M13: =B13/C13 -> 56.096979 | N13: =J13/K13 -> 16.219217 | O13: =1/M13 -> 0.017826272 | P13: =1/N13 -> 0.061655259 | S13: =0.1035*((A13-((57.3*J13)/(PI()*3.6)))-(-4.313)) -> 0.44008977 | T13: =J13^2/(PI()*'Wing Info. (Ref)'!$F$11*'Wing Info. (Ref)'!$E$6) -> 0.013772992 | U13: 0.011 | V13: =T13+U13 -> 0.024772992
A14: 0 | B14: 0.4465 | C14: 0.01159 | D14: 0.00512 | E14: -0.0962 | F14: 0.6354 | G14: 0.6915 | I14: ='Wing Info. (Ref)'!$H$6*('Wing Chract. (Ref)'!A14-'Wing Info. (Ref)'!$G$6) -> 0.4465 | J14: ='Wing Info. (Ref)'!$J$6*('Wing Chract. (Ref)'!A14-'Wing Info. (Ref)'!$G$6) -> 0.27791688 | K14: 0.018952296 | M14: =B14/C14 -> 38.52459 | N14: =J14/K14 -> 14.664021 | O14: =1/M14 -> 0.025957447 | P14: =1/N14 -> 0.068194118 | S14: =0.1035*((A14-((57.3*J14)/(PI()*3.6)))-(-4.313)) -> 0.30066263 | T14: =J14^2/(PI()*'Wing Info. (Ref)'!$F$11*'Wing Info. (Ref)'!$E$6) -> 0.0064289243 | U14: 0.01238 | V14: =T14+U14 -> 0.018808924
A15: -2 | B15: 0.2472 | C15: 0.01278 | D15: 0.00526 | E15: -0.1019 | F15: 0.7142 | G15: 0.3175 | I15: ='Wing Info. (Ref)'!$H$6*('Wing Chract. (Ref)'!A15-'Wing Info. (Ref)'!$G$6) -> 0.2394686 | J15: ='Wing Info. (Ref)'!$J$6*('Wing Chract. (Ref)'!A15-'Wing Info. (Ref)'!$G$6) -> 0.14905345 | K15: 0.015230477 | M15: =B15/C15 -> 19.342723 | N15: =J15/K15 -> 9.7865255 | O15: =1/M15 -> 0.051699029 | P15: =1/N15 -> 0.10218131 | S15: =0.1035*((A15-((57.3*J15)/(PI()*3.6)))-(-4.313)) -> 0.16123549 | T15: =J15^2/(PI()*'Wing Info. (Ref)'!$F$11*'Wing Info. (Ref)'!$E$6) -> 0.0018492368 | U15: 0.01334 | V15: =T15+U15 -> 0.015189237
A16: -4 | B16: 0.0332 | C16: 0.01417 | D16: 0.00665 | E16: -0.1049 | F16: 0.7958 | G16: 0.1956 | I16: ='Wing Info. (Ref)'!$H$6*('Wing Chract. (Ref)'!A16-'Wing Info. (Ref)'!$G$6) -> 0.032437199 | J16: ='Wing Info. (Ref)'!$J$6*('Wing Chract. (Ref)'!A16-'Wing Info. (Ref)'!$G$6) -> 0.020190023 | K16: 0.014344687 | M16: =B16/C16 -> 2.3429781 | N16: =J16/K16 -> 1.4074914 | O16: =1/M16 -> 0.42680723 | P16: =1/N16 -> 0.71048393 | S16: =0.1035*((A16-((57.3*J16)/(PI()*3.6)))-(-4.313)) -> 0.021808342 | T16: =J16^2/(PI()*'Wing Info. (Ref)'!$F$11*'Wing Info. (Ref)'!$E$6) -> 3.3929861e-05 | U16: 0.01431 | V16: =T16+U16 -> 0.01434393
A17: -6 | B17: -0.1787 | C17: 0.01675 | D17: 0.0092 | E17: -0.1081 | F17: 0.8655 | G17: 0.1305 | I17: ='Wing Info. (Ref)'!$H$6*('Wing Chract. (Ref)'!A17-'Wing Info. (Ref)'!$G$6) -> -0.1745942 | J17: ='Wing Info. (Ref)'!$J$6*('Wing Chract. (Ref)'!A17-'Wing Info. (Ref)'!$G$6) -> -0.1086734 | K17: 0.017004925 | M17: =B17/C17 -> -10.668657 | N17: =J17/K17 -> -6.3907016 | O17: =1/M17 -> -0.093732513 | P17: =1/N17 -> -0.15647734 | S17: =0.1035*((A17-((57.3*J17)/(PI()*3.6)))-(-4.313)) -> -0.1176188 | T17: =J17^2/(PI()*'Wing Info. (Ref)'!$F$11*'Wing Info. (Ref)'!$E$6) -> 0.00098300339 | U17: 0.016 | V17: =T17+U17 -> 0.016983003
A18: -8 | B18: -0.4096 | C18: 0.02098 | D18: 0.01368 | E18: -0.1073 | F18: 0.9127 | G18: 0.0941 | I18: ='Wing Info. (Ref)'!$H$6*('Wing Chract. (Ref)'!A18-'Wing Info. (Ref)'!$G$6) -> -0.3816256 | J18: ='Wing Info. (Ref)'!$J$6*('Wing Chract. (Ref)'!A18-'Wing Info. (Ref)'!$G$6) -> -0.23753683 | K18: 0.022901193 | M18: =B18/C18 -> -19.523356 | N18: =J18/K18 -> -10.372247 | O18: =1/M18 -> -0.051220703 | P18: =1/N18 -> -0.096411126 | S18: =0.1035*((A18-((57.3*J18)/(PI()*3.6)))-(-4.313)) -> -0.25704595 | T18: =J18^2/(PI()*'Wing Info. (Ref)'!$F$11*'Wing Info. (Ref)'!$E$6) -> 0.0046964574 | U18: 0.0181 | V18: =T18+U18 -> 0.022796457
A19: -10 | B19: -0.6713 | C19: 0.02747 | D19: 0.02059 | E19: -0.0973 | F19: 0.9462 | G19: 0.0726 | I19: ='Wing Info. (Ref)'!$H$6*('Wing Chract. (Ref)'!A19-'Wing Info. (Ref)'!$G$6) -> -0.588657 | J19: ='Wing Info. (Ref)'!$J$6*('Wing Chract. (Ref)'!A19-'Wing Info. (Ref)'!$G$6) -> -0.36640026 | K19: 0.032623491 | M19: =B19/C19 -> -24.437568 | N19: =J19/K19 -> -11.231179 | O19: =1/M19 -> -0.040920602 | P19: =1/N19 -> -0.089037849 | S19: =0.1035*((A19-((57.3*J19)/(PI()*3.6)))-(-4.313)) -> -0.39647309 | T19: =J19^2/(PI()*'Wing Info. (Ref)'!$F$11*'Wing Info. (Ref)'!$E$6) -> 0.011174292 | U19: 0.0212 | V19: =T19+U19 -> 0.032374292
A20: -12 | B20: -0.8847 | C20: 0.03756 | D20: 0.03172 | E20: -0.0885 | F20: 0.9821 | G20: 0.0601 | I20: ='Wing Info. (Ref)'!$H$6*('Wing Chract. (Ref)'!A20-'Wing Info. (Ref)'!$G$6) -> -0.7956884 | J20: ='Wing Info. (Ref)'!$J$6*('Wing Chract. (Ref)'!A20-'Wing Info. (Ref)'!$G$6) -> -0.49526369 | K20: 0.041671817 | M20: =B20/C20 -> -23.554313 | N20: =J20/K20 -> -11.884859 | O20: =1/M20 -> -0.04245507 | P20: =1/N20 -> -0.084140668 | S20: =0.1035*((A20-((57.3*J20)/(PI()*3.6)))-(-4.313)) -> -0.53590023 | T20: =J20^2/(PI()*'Wing Info. (Ref)'!$F$11*'Wing Info. (Ref)'!$E$6) -> 0.020416507 | U20: 0.0208 | V20: =T20+U20 -> 0.041216507
A21: -14 | B21: -0.8142 | C21: 0.05454 | D21: 0.04975 | E21: -0.0987 | F21: 1 | G21: 0.056 | M21: =B21/C21 -> -14.928493 | O21: =1/M21 -> -0.066985999
A22: -16 | B22: -0.2254 | C22: 0.16083 | D22: 0.15756 | E22: -0.0414 | F22: 1 | G22: 0.0633 | M22: =B22/C22 -> -1.4014798 | O22: =1/M22 -> -0.7135315
A23: -18 | B23: -0.2204 | C23: 0.17191 | D23: 0.16853 | E23: -0.0422 | F23: 1 | G23: 0.0552 | M23: =B23/C23 -> -1.2820662 | O23: =1/M23 -> -0.77999093
I25: Cl 8 | J25: CL 8
I26: =I10 -> 1.2746256 | J26: =J10 -> 0.79337058

Sheet Wing Mid.
A1: Airfoil: | B1: NACA4418 | D1: Desired Weight (lb): | E1: 7.5 | H1: in2 | I1: ft2 | K1: Taper Ratio | L1: Mean Aerodynamic Chord | M1: Y bar | V1: T/W
A2: Re #: | B2: 250000 | D2: Desired Vcruise (ft/s): | E2: 40 | G2: Surface Area | H2: 440.74 | I2: =H2/144 -> 3.0606944 | K2: =C7/B7 -> 0.25 | L2: =(2/3)*B7*(1+K2+K2^2)/(1+K2) -> 16.8 | M2: =(12*E3/6)*((1+2*K2)/(1+K2)) -> 10.8 | P2: alpha | Q2: Linealized Cl | R2: CL | S2: CD | T2: CM | U2: L/D | V2: 1/(L/D)
A3: t/c | B3: 0.18 | D3: Desired Wing Span (ft): | E3: 4.5 | P3: ------ | Q3: -------- | R3: -------- | S3: -------- | T3: -------- | U3: -------- | V3: --------
A4: Density (slug/ft3): | B4: 0.00228782 | G4: αCl=0 | H4: a0 (0-8) | J4: a (0-8) | M4: m0 | P4: 20
E5: e | G5: deg | H5: /deg | I5: /rad | J5: /deg | K5: /rad | M5: /deg | N5: /rad | P5: 18
B6: Root | C6: Tip | E6: =4.61*(1-0.045*F11^(0.68))*(COS(C12))^0.15-3.1 -> 0.75291482 | G6: =('Wing Chract. (Ref)'!A16)-(('Wing Chract. (Ref)'!B16)/(('Wing Chract. (Ref)'!B16-'Wing Chract. (Ref)'!B17)/('Wing Chract. (Ref)'!A16-'Wing Chract. (Ref)'!A17))) -> -4.3133554 | H6: =('Wing Chract. (Ref)'!B14-0)/(0-'Wing Info. (Ref)'!G6) -> 0.1035157 | I6: =H6*180/PI() -> 5.9310127 | J6: =K6*PI()/180 -> 0.077918523 | K6: =I6*COS(C11)/(SQRT(1+(I6*COS(C11)/(PI()*F11))^2)+(I6*COS(C11)/(PI()*F11))) -> 4.4644025 | M6: =('Wing Chract. (Ref)'!E12-'Wing Chract. (Ref)'!E17)/('Wing Chract. (Ref)'!A12-'Wing Chract. (Ref)'!A17) -> 0.00055 | N6: =M6*180/PI() -> 0.031512679 | P6: 16 | X6: cl | Y6: cl2/piar | Z6: cd
A7: Chord | B7: 24 | C7: 6 | H7: =('Wing Chract. (Ref)'!B8-'Wing Chract. (Ref)'!B9)/('Wing Chract. (Ref)'!A8-'Wing Chract. (Ref)'!A9) -> 0.04385 | I7: =H7*180/PI() -> 2.5124199 | J7: =K7*PI()/180 -> 0.038753565 | K7: =I7*COS(C11)/(SQRT(1+(I7*COS(C11)/(PI()*F11))^2)+(I7*COS(C11)/(PI()*F11))) -> 2.2204157 | P7: 14 | Q7: =$H$7*(P7-$P$10)+$Q$27 -> 1.5377256 | R7: =$J$7*(P7-$P$10)+$R$27 -> 1.1919599 | U7: =R7/S7 -> #DIV/0! | V7: =1/U7 -> #DIV/0! | X7: =0.1035*((P7-((57.3*R7)/(PI()*3.6)))-(-4.313)) -> 1.2703607 | Y7: =R7^2/(PI()*$E$6*$F$11) -> 0.090786753 | AA7: =Y7+Z7 -> 0.090786753
A8: Thickness | B8: =B7*B3 -> 4.32 | C8: =C7*B3 -> 1.08 | H8: a0 (8-16) | J8: a (8-16) | P8: 12 | Q8: =$H$7*(P8-$P$10)+$Q$27 -> 1.4500256 | R8: =$J$7*(P8-$P$10)+$R$27 -> 1.1144527 | U8: =R8/S8 -> #DIV/0! | V8: =1/U8 -> #DIV/0! | X8: =0.1035*((P8-((57.3*R8)/(PI()*3.6)))-(-4.313)) -> 1.1040035 | Y8: =R8^2/(PI()*$E$6*$F$11) -> 0.079363814 | AA8: =Y8+Z8 -> 0.079363814
P9: 10 | Q9: =$H$7*(P9-$P$10)+$Q$27 -> 1.3623256 | R9: =$J$7*(P9-$P$10)+$R$27 -> 1.0369456 | U9: =R9/S9 -> #DIV/0! | V9: =1/U9 -> #DIV/0! | X9: =0.1035*((P9-((57.3*R9)/(PI()*3.6)))-(-4.313)) -> 0.93764638 | Y9: =R9^2/(PI()*$E$6*$F$11) -> 0.068708611 | AA9: =Y9+Z9 -> 0.068708611
B10: deg | C10: rad | F10: Aspect Ratio | G10: xac (%) | H10: Vstall (ft/s) | I10: Vcruise (ft/s) | J10: Lift takeoff (lb) | K10: Lift cruise (lb) | L10: Lift Cruise Desired V (lb) | P10: 8 | Q10: =$H$6*(P10-$G$6) -> 1.2746256 | R10: =$J$6*(P10-$G$6) -> 0.95943846 | U10: =R10/S10 -> #DIV/0! | V10: =1/U10 -> #DIV/0! | X10: =0.1035*((P10-((57.3*R10)/(PI()*3.6)))-(-4.313)) -> 0.77128924 | Y10: =R10^2/(PI()*$E$6*$F$11) -> 0.058821146 | AA10: =Y10+Z10 -> 0.058821146
A11: Sweep Angle 0.5c | B11: 4.7035 | C11: =B11*PI()/180 -> 0.082091561 | E11: 2D | F11: =E3^2/I2 -> 6.6161456 | G11: =((-M6/H6)+0.25)*100 -> 24.46868 | H11: =SQRT((2*$E$1)/($B$4*$I$2*'Wing Chract. (Ref)'!B9)) -> 39.084472 | I11: =SQRT((2*$E$1)/($B$4*$I$2*'Wing Chract. (Ref)'!$B$14)) -> 69.265023 | J11: =0.5*'Wing Chract. (Ref)'!B9*$I$2*$B$4*$H$11^2 -> 7.5 | K11: =0.5*'Wing Chract. (Ref)'!$B$14*$I$2*$B$4*$I$11^2 -> 7.5 | L11: =0.5*'Wing Chract. (Ref)'!$B$14*$I$2*$B$4*$E$2^2 -> 2.501228 | P11: 6 | Q11: =$H$6*(P11-$G$6) -> 1.0675942 | R11: =$J$6*(P11-$G$6) -> 0.80360142 | U11: =R11/S11 -> #DIV/0! | V11: =1/U11 -> #DIV/0! | X11: =0.1035*((P11-((57.3*R11)/(PI()*3.6)))-(-4.313)) -> 0.6460064 | Y11: =R11^2/(PI()*$E$6*$F$11) -> 0.041264883 | AA11: =Y11+Z11 -> 0.041264883
A12: Sweep Angle LE | B12: 9.096 | C12: =B12*PI()/180 -> 0.15875515 | E12: 3D | G12: =((-M6/J6)+0.25)*100 -> 24.294134 | H12: =SQRT((2*$E$1)/($B$4*$I$2*R7)) -> 42.392976 | I12: =SQRT((2*$E$1)/($B$4*$I$2*R14)) -> 79.835627 | J12: =0.5*R7*$I$2*$B$4*$H$12^2 -> 7.5 | K12: =0.5*R14*$I$2*$B$4*$I$12^2 -> 7.5 | L12: =0.5*R14*$I$2*$B$4*$E$2^2 -> 1.8827288 | P12: 4 | Q12: =$H$6*(P12-$G$6) -> 0.8605628 | R12: =$J$6*(P12-$G$6) -> 0.64776437 | U12: =R12/S12 -> #DIV/0! | V12: =1/U12 -> #DIV/0! | X12: =0.1035*((P12-((57.3*R12)/(PI()*3.6)))-(-4.313)) -> 0.52072357 | Y12: =R12^2/(PI()*$E$6*$F$11) -> 0.026812255 | AA12: =Y12+Z12 -> 0.026812255
P13: 2 | Q13: =$H$6*(P13-$G$6) -> 0.6535314 | R13: =$J$6*(P13-$G$6) -> 0.49192733 | U13: =R13/S13 -> #DIV/0! | V13: =1/U13 -> #DIV/0! | X13: =0.1035*((P13-((57.3*R13)/(PI()*3.6)))-(-4.313)) -> 0.39544074 | Y13: =R13^2/(PI()*$E$6*$F$11) -> 0.015463262 | AA13: =Y13+Z13 -> 0.015463262
P14: 0 | Q14: =$H$6*(P14-$G$6) -> 0.4465 | R14: =$J$6*(P14-$G$6) -> 0.33609028 | S14: 0.018952296 | U14: =R14/S14 -> 17.733486 | V14: =1/U14 -> 0.056390492 | X14: =0.1035*((P14-((57.3*R14)/(PI()*3.6)))-(-4.313)) -> 0.27015791 | Y14: =R14^2/(PI()*$E$6*$F$11) -> 0.0072179045 | Z14: 0.012423 | AA14: =Y14+Z14 -> 0.019640905
P15: -2 | Q15: =$H$6*(P15-$G$6) -> 0.2394686 | R15: =$J$6*(P15-$G$6) -> 0.18025323 | U15: =R15/S15 -> #DIV/0! | V15: =1/U15 -> #DIV/0! | X15: =0.1035*((P15-((57.3*R15)/(PI()*3.6)))-(-4.313)) -> 0.14487508 | Y15: =R15^2/(PI()*$E$6*$F$11) -> 0.0020761817 | AA15: =Y15+Z15 -> 0.0020761817
P16: -4 | Q16: =$H$6*(P16-$G$6) -> 0.032437199 | R16: =$J$6*(P16-$G$6) -> 0.024416187 | U16: =R16/S16 -> #DIV/0! | V16: =1/U16 -> #DIV/0! | X16: =0.1035*((P16-((57.3*R16)/(PI()*3.6)))-(-4.313)) -> 0.019592244 | Y16: =R16^2/(PI()*$E$6*$F$11) -> 3.8093853e-05 | AA16: =Y16+Z16 -> 3.8093853e-05
P17: -6 | Q17: =$H$6*(P17-$G$6) -> -0.1745942 | R17: =$J$6*(P17-$G$6) -> -0.13142086 | U17: =R17/S17 -> #DIV/0! | V17: =1/U17 -> #DIV/0! | X17: =0.1035*((P17-((57.3*R17)/(PI()*3.6)))-(-4.313)) -> -0.10569059 | Y17: =R17^2/(PI()*$E$6*$F$11) -> 0.001103641 | AA17: =Y17+Z17 -> 0.001103641
P18: -8 | Q18: =$H$6*(P18-$G$6) -> -0.3816256 | R18: =$J$6*(P18-$G$6) -> -0.28725791 | U18: =R18/S18 -> #DIV/0! | V18: =1/U18 -> #DIV/0! | X18: =0.1035*((P18-((57.3*R18)/(PI()*3.6)))-(-4.313)) -> -0.23097342 | Y18: =R18^2/(PI()*$E$6*$F$11) -> 0.0052728232 | AA18: =Y18+Z18 -> 0.0052728232
P19: -10 | Q19: =$H$6*(P19-$G$6) -> -0.588657 | R19: =$J$6*(P19-$G$6) -> -0.44309495 | U19: =R19/S19 -> #DIV/0! | V19: =1/U19 -> #DIV/0! | X19: =0.1035*((P19-((57.3*R19)/(PI()*3.6)))-(-4.313)) -> -0.35625625 | Y19: =R19^2/(PI()*$E$6*$F$11) -> 0.01254564 | AA19: =Y19+Z19 -> 0.01254564
P20: -12 | Q20: =$H$6*(P20-$G$6) -> -0.7956884 | R20: =$J$6*(P20-$G$6) -> -0.598932 | U20: =R20/S20 -> #DIV/0! | V20: =1/U20 -> #DIV/0! | X20: =0.1035*((P20-((57.3*R20)/(PI()*3.6)))-(-4.313)) -> -0.48153908 | Y20: =R20^2/(PI()*$E$6*$F$11) -> 0.022922093 | AA20: =Y20+Z20 -> 0.022922093
P21: -14
P22: -16
P23: -18
T25: V | U25: Cruise Lift | V25: Max Lift
Q26: Cl 8 | R26: CL 8 | T26: 65 | U26: =0.5*$R$14*$B$4*$I$2*T26^2 -> 4.9715807 | V26: =0.5*$R$7*$B$4*$I$2*T26^2 -> 17.631943
Q27: =Q10 -> 1.2746256 | R27: =R10 -> 0.95943846 | T27: 70 | U27: =0.5*$R$14*$B$4*$I$2*T27^2 -> 5.7658569 | V27: =0.5*$R$7*$B$4*$I$2*T27^2 -> 20.448881
T28: 75 | U28: =0.5*$R$14*$B$4*$I$2*T28^2 -> 6.6189684 | V28: =0.5*$R$7*$B$4*$I$2*T28^2 -> 23.47448
T29: 80 | U29: =0.5*$R$14*$B$4*$I$2*T29^2 -> 7.5309152 | V29: =0.5*$R$7*$B$4*$I$2*T29^2 -> 26.708742
T30: 85 | U30: =0.5*$R$14*$B$4*$I$2*T30^2 -> 8.5016972 | V30: =0.5*$R$7*$B$4*$I$2*T30^2 -> 30.151666
T31: 90 | U31: =0.5*$R$14*$B$4*$I$2*T31^2 -> 9.5313145 | V31: =0.5*$R$7*$B$4*$I$2*T31^2 -> 33.803252
T32: 95 | U32: =0.5*$R$14*$B$4*$I$2*T32^2 -> 10.619767 | V32: =0.5*$R$7*$B$4*$I$2*T32^2 -> 37.6635
T33: 100 | U33: =0.5*$R$14*$B$4*$I$2*T33^2 -> 11.767055 | V33: =0.5*$R$7*$B$4*$I$2*T33^2 -> 41.732409
T34: 105 | U34: =0.5*$R$14*$B$4*$I$2*T34^2 -> 12.973178 | V34: =0.5*$R$7*$B$4*$I$2*T34^2 -> 46.009981
T35: 110 | U35: =0.5*$R$14*$B$4*$I$2*T35^2 -> 14.238137 | V35: =0.5*$R$7*$B$4*$I$2*T35^2 -> 50.496215
T36: 115 | U36: =0.5*$R$14*$B$4*$I$2*T36^2 -> 15.56193 | V36: =0.5*$R$7*$B$4*$I$2*T36^2 -> 55.191112
T37: 120 | U37: =0.5*$R$14*$B$4*$I$2*T37^2 -> 16.944559 | V37: =0.5*$R$7*$B$4*$I$2*T37^2 -> 60.09467
T38: 125 | U38: =0.5*$R$14*$B$4*$I$2*T38^2 -> 18.386023 | V38: =0.5*$R$7*$B$4*$I$2*T38^2 -> 65.20689
T39: 40 | U39: =0.5*$S$14*$B$4*$I$2*T39^2 -> 0.106168 | V39: =0.5*$R$7*$B$4*$I$2*T39^2 -> 6.6771855

Sheet Horizontal Info.
A1: Airfoil: | B1: NACA0006 | D1: Desired Weight (lb): | E1: 8 | H1: in2 | I1: ft2 | K1: Taper Ratio | L1: Mean Aerodynamic Chord | M1: Y bar
A2: Re #: | B2: 250000 | D2: Desired Vcruise (ft/s): | E2: 80 | G2: Surface Area | H2: 129.6 | I2: =H2/144 -> 0.9 | K2: =C7/B7 -> 1 | L2: =(2/3)*B7*(1+K2+K2^2)/(1+K2) -> 6 | M2: =(12*E3/6)*((1+2*K2)/(1+K2)) -> 5.4
A3: t/c | B3: 0.06 | D3: Desired Wing Span (ft): | E3: 1.8
A4: Density (slug/ft3): | B4: 0.00228782 | G4: αCl=0 | H4: a0 (0-8) | J4: a (0-8) | M4: m0
E5: e | G5: deg | H5: /deg | I5: /rad | J5: /deg | K5: /rad | M5: /deg | N5: /rad
B6: Root | C6: Tip | E6: =4.61*(1-0.045*F9^(0.68))*(COS(C12))^0.15-3.1 -> 1.0143226 | G6: 0 | H6: =('Horizontal Chract.'!B6-'Horizontal Chract.'!B9)/('Horizontal Chract.'!A6-'Horizontal Chract.'!A9) -> 0.10496667 | I6: =H6*180/PI() -> 6.014147 | J6: =K6*PI()/180 -> 0.063067111 | K6: =I6*COS(C11)/(SQRT(1+(I6*COS(C11)/(PI()*F9))^2)+(I6*COS(C11)/(PI()*F9))) -> 3.6134793 | M6: =('Horizontal Chract.'!E7-'Horizontal Chract.'!E11)/('Horizontal Chract.'!A7-'Horizontal Chract.'!A11) -> 0.00035 | N6: =M6*180/PI() -> 0.020053523
A7: Chord | B7: 6 | C7: 6
A8: Thickness | B8: =B7*B3 -> 0.36 | C8: =C7*B3 -> 0.36 | F8: Aspect Ratio | G8: xac (%) | H8: Lift Cruise Desired V (lb)
E9: 2D | F9: =E3^2/I2 -> 3.6 | G9: =((-M6/H6)+0.25)*100 -> 24.666561 | H9: =0.5*'Horizontal Chract.'!$B$9*$I$2*$B$4*$E$2^2 -> 0
B10: deg | C10: rad | E10: 3D | H10: =0.5*'Horizontal Chract.'!$J$9*$I$2*$B$4*$E$2^2 -> 0
A11: Sweep Angle 0.5c | B11: 0 | C11: =B11*PI()/180 -> 0
A12: Sweep Angle LE | B12: 0 | C12: =B12*PI()/180 -> 0

Sheet Horizontal Chract.
O1: t/w | P1: T/W
A2: alpha | B2: Cl | C2: Cd | D2: Cdp | E2: Cm | F2: Top_Xtr | G2: Bot_Xtr | I2: Linealized Cl | J2: CL | K2: CD | L2: CM | M2: l/d | N2: L/D | O2: 1/(l/d) | P2: 1/(L/D)
A3: ------ | B3: -------- | C3: --------- | D3: --------- | E3: -------- | F3: -------- | G3: -------- | I3: -------- | J3: -------- | K3: -------- | L3: -------- | M3: -------- | N3: -------- | O3: -------- | P3: -------- | S3: cl | T3: cl2/piar | U3: cd
A4: 10 | B4: 0.707 | C4: 0.11639 | D4: 0.11355 | E4: -0.0318 | F4: 0.0231 | G4: 1 | I4: ='Horizontal Info.'!$H$6*('Horizontal Chract.'!A4-'Horizontal Chract.'!$A$9) -> 1.0496667 | J4: ='Horizontal Info.'!$J$6*('Horizontal Chract.'!A4-'Horizontal Chract.'!$A$9) -> 0.63067111 | M4: =B4/C4 -> 6.074405 | N4: =J4/K4 -> #DIV/0! | O4: =1/M4 -> 0.16462518 | P4: =1/N4 -> #DIV/0! | S4: =0.1035*((A4-((57.3*J4)/(PI()*3.6)))-(-4.313)) -> 1.1506869 | T4: =J4^2/(PI()*'Horizontal Info.'!$F$9*'Horizontal Info.'!$E$6) -> 0.034671882 | V4: =T4+U4 -> 0.034671882
A5: 7 | B5: 0.6952 | C5: 0.04909 | D5: 0.04532 | E5: 0.0111 | F5: 0.0311 | G5: 1 | I5: ='Horizontal Info.'!$H$6*('Horizontal Chract.'!A5-'Horizontal Chract.'!$A$9) -> 0.73476667 | J5: ='Horizontal Info.'!$J$6*('Horizontal Chract.'!A5-'Horizontal Chract.'!$A$9) -> 0.44146978 | M5: =B5/C5 -> 14.161744 | N5: =J5/K5 -> #DIV/0! | O5: =1/M5 -> 0.070612773 | P5: =1/N5 -> #DIV/0! | S5: =0.1035*((A5-((57.3*J5)/(PI()*3.6)))-(-4.313)) -> 0.93939945 | T5: =J5^2/(PI()*'Horizontal Info.'!$F$9*'Horizontal Info.'!$E$6) -> 0.016989222 | V5: =T5+U5 -> 0.016989222
A6: 6 | B6: 0.6298 | C6: 0.03542 | D6: 0.03085 | E6: 0.0105 | F6: 0.0377 | G6: 1 | I6: ='Horizontal Info.'!$H$6*('Horizontal Chract.'!A6-'Horizontal Chract.'!$A$9) -> 0.6298 | J6: ='Horizontal Info.'!$J$6*('Horizontal Chract.'!A6-'Horizontal Chract.'!$A$9) -> 0.37840267 | M6: =B6/C6 -> 17.780915 | N6: =J6/K6 -> #DIV/0! | O6: =1/M6 -> 0.056240076 | P6: =1/N6 -> #DIV/0! | S6: =0.1035*((A6-((57.3*J6)/(PI()*3.6)))-(-4.313)) -> 0.86897032 | T6: =J6^2/(PI()*'Horizontal Info.'!$F$9*'Horizontal Info.'!$E$6) -> 0.012481877 | V6: =T6+U6 -> 0.012481877
A7: 4 | B7: 0.4397 | C7: 0.01259 | D7: 0.0052 | E7: 0.0014 | F7: 0.0327 | G7: 1 | I7: ='Horizontal Info.'!$H$6*('Horizontal Chract.'!A7-'Horizontal Chract.'!$A$9) -> 0.41986667 | J7: ='Horizontal Info.'!$J$6*('Horizontal Chract.'!A7-'Horizontal Chract.'!$A$9) -> 0.25226845 | M7: =B7/C7 -> 34.924543 | N7: =J7/K7 -> #DIV/0! | O7: =1/M7 -> 0.028633159 | P7: =1/N7 -> #DIV/0! | S7: =0.1035*((A7-((57.3*J7)/(PI()*3.6)))-(-4.313)) -> 0.72811205 | T7: =J7^2/(PI()*'Horizontal Info.'!$F$9*'Horizontal Info.'!$E$6) -> 0.0055475011 | V7: =T7+U7 -> 0.0055475011
A8: 2 | B8: 0.2568 | C8: 0.00619 | D8: 0.00189 | E8: -0.0066 | F8: 0.8248 | G8: 1 | I8: ='Horizontal Info.'!$H$6*('Horizontal Chract.'!A8-'Horizontal Chract.'!$A$9) -> 0.20993333 | J8: ='Horizontal Info.'!$J$6*('Horizontal Chract.'!A8-'Horizontal Chract.'!$A$9) -> 0.12613422 | M8: =B8/C8 -> 41.486268 | N8: =J8/K8 -> #DIV/0! | O8: =1/M8 -> 0.024104361 | P8: =1/N8 -> #DIV/0! | S8: =0.1035*((A8-((57.3*J8)/(PI()*3.6)))-(-4.313)) -> 0.58725377 | T8: =J8^2/(PI()*'Horizontal Info.'!$F$9*'Horizontal Info.'!$E$6) -> 0.0013868753 | V8: =T8+U8 -> 0.0013868753
A9: 0 | B9: 0 | C9: 0.00603 | D9: 0.0016 | E9: 0 | F9: 1 | G9: 1 | I9: ='Horizontal Info.'!$H$6*('Horizontal Chract.'!A9-'Horizontal Chract.'!$A$9) -> 0 | J9: ='Horizontal Info.'!$J$6*('Horizontal Chract.'!A9-'Horizontal Chract.'!$A$9) -> 0 | K9: 0.013 | M9: =B9/C9 -> 0 | N9: =J9/K9 -> 0 | O9: =1/M9 -> #DIV/0! | P9: =1/N9 -> #DIV/0! | S9: =0.1035*((A9-((57.3*J9)/(PI()*3.6)))-(-4.313)) -> 0.4463955 | T9: =J9^2/(PI()*'Horizontal Info.'!$F$9*'Horizontal Info.'!$E$6) -> 0 | U9: 0.013 | V9: =T9+U9 -> 0.013
A10: -2 | B10: -0.2569 | C10: 0.00619 | D10: 0.00189 | E10: 0.0066 | F10: 1 | G10: 0.8249 | I10: ='Horizontal Info.'!$H$6*('Horizontal Chract.'!A10-'Horizontal Chract.'!$A$9) -> -0.20993333 | J10: ='Horizontal Info.'!$J$6*('Horizontal Chract.'!A10-'Horizontal Chract.'!$A$9) -> -0.12613422 | M10: =B10/C10 -> -41.502423 | N10: =J10/K10 -> #DIV/0! | O10: =1/M10 -> -0.024094979 | P10: =1/N10 -> #DIV/0! | S10: =0.1035*((A10-((57.3*J10)/(PI()*3.6)))-(-4.313)) -> 0.30553723 | T10: =J10^2/(PI()*'Horizontal Info.'!$F$9*'Horizontal Info.'!$E$6) -> 0.0013868753 | V10: =T10+U10 -> 0.0013868753
A11: -4 | B11: -0.4397 | C11: 0.01259 | D11: 0.00519 | E11: -0.0014 | F11: 1 | G11: 0.0327 | I11: ='Horizontal Info.'!$H$6*('Horizontal Chract.'!A11-'Horizontal Chract.'!$A$9) -> -0.41986667 | J11: ='Horizontal Info.'!$J$6*('Horizontal Chract.'!A11-'Horizontal Chract.'!$A$9) -> -0.25226845 | M11: =B11/C11 -> -34.924543 | N11: =J11/K11 -> #DIV/0! | O11: =1/M11 -> -0.028633159 | P11: =1/N11 -> #DIV/0! | S11: =0.1035*((A11-((57.3*J11)/(PI()*3.6)))-(-4.313)) -> 0.16467895 | T11: =J11^2/(PI()*'Horizontal Info.'!$F$9*'Horizontal Info.'!$E$6) -> 0.0055475011 | V11: =T11+U11 -> 0.0055475011
A12: -6 | B12: -0.6298 | C12: 0.03542 | D12: 0.03085 | E12: -0.0105 | F12: 0.0377 | G12: 1 | I12: ='Horizontal Info.'!$H$6*('Horizontal Chract.'!A12-'Horizontal Chract.'!$A$9) -> -0.6298 | J12: ='Horizontal Info.'!$J$6*('Horizontal Chract.'!A12-'Horizontal Chract.'!$A$9) -> -0.37840267 | M12: =B12/C12 -> -17.780915 | N12: =J12/K12 -> #DIV/0! | O12: =1/M12 -> -0.056240076 | P12: =1/N12 -> #DIV/0! | S12: =0.1035*((A12-((57.3*J12)/(PI()*3.6)))-(-4.313)) -> 0.023820682 | T12: =J12^2/(PI()*'Horizontal Info.'!$F$9*'Horizontal Info.'!$E$6) -> 0.012481877 | V12: =T12+U12 -> 0.012481877
A13: -7 | B13: -0.6952 | C13: 0.04909 | D13: 0.04532 | E13: -0.0111 | F13: 0.0311 | G13: 1 | I13: ='Horizontal Info.'!$H$6*('Horizontal Chract.'!A13-'Horizontal Chract.'!$A$9) -> -0.73476667 | J13: ='Horizontal Info.'!$J$6*('Horizontal Chract.'!A13-'Horizontal Chract.'!$A$9) -> -0.44146978 | M13: =B13/C13 -> -14.161744 | N13: =J13/K13 -> #DIV/0! | O13: =1/M13 -> -0.070612773 | P13: =1/N13 -> #DIV/0! | S13: =0.1035*((A13-((57.3*J13)/(PI()*3.6)))-(-4.313)) -> -0.046608454 | T13: =J13^2/(PI()*'Horizontal Info.'!$F$9*'Horizontal Info.'!$E$6) -> 0.016989222 | V13: =T13+U13 -> 0.016989222
A14: -10 | B14: -0.707 | C14: 0.11639 | D14: 0.11355 | E14: -0.0318 | F14: 0.0231 | G14: 1 | I14: ='Horizontal Info.'!$H$6*('Horizontal Chract.'!A14-'Horizontal Chract.'!$A$9) -> -1.0496667 | J14: ='Horizontal Info.'!$J$6*('Horizontal Chract.'!A14-'Horizontal Chract.'!$A$9) -> -0.63067111 | M14: =B14/C14 -> -6.074405 | N14: =J14/K14 -> #DIV/0! | O14: =1/M14 -> -0.16462518 | P14: =1/N14 -> #DIV/0! | S14: =0.1035*((A14-((57.3*J14)/(PI()*3.6)))-(-4.313)) -> -0.25789586 | T14: =J14^2/(PI()*'Horizontal Info.'!$F$9*'Horizontal Info.'!$E$6) -> 0.034671882 | V14: =T14+U14 -> 0.034671882

Sheet Vertical Info.
A1: Airfoil: | B1: NACA0009 | D1: Desired Weight (lb): | E1: 8 | H1: in2 | I1: ft2 | K1: Taper Ratio | L1: Mean Aerodynamic Chord | M1: Y bar
A2: Re #: | B2: 250000 | D2: Desired Vcruise (ft/s): | E2: 80 | G2: Surface Area | H2: 0.29583 | I2: =H2/144 -> 0.002054375 | K2: =C7/B7 -> 1 | L2: =(2/3)*B7*(1+K2+K2^2)/(1+K2) -> 6 | M2: =(12*E3/6)*((1+2*K2)/(1+K2)) -> 1.77501
A3: t/c | B3: 0.09 | D3: Desired Wing Span (ft): | E3: 0.59167
A4: Density (slug/ft3): | B4: 0.00228782 | G4: αCl=0 | H4: a0 (0-8) | J4: a (0-8) | M4: m0
E5: e | G5: deg | H5: /deg | I5: /rad | J5: /deg | K5: /rad | M5: /deg | N5: /rad
B6: Root | C6: Tip | E6: =4.61*(1-0.045*F9^(0.68))*(COS(C12))^0.15-3.1 -> -5.3184073 | G6: 0 | H6: =('Vertical Chract.'!B6-'Vertical Chract.'!B9)/('Vertical Chract.'!A6-'Vertical Chract.'!A9) -> 0.10645 | I6: =H6*180/PI() -> 6.0991357 | J6: =K6*PI()/180 -> 0.10524412 | K6: =I6*COS(C11)/(SQRT(1+(I6*COS(C11)/(PI()*F9))^2)+(I6*COS(C11)/(PI()*F9))) -> 6.0300439 | M6: =('Vertical Chract.'!E7-'Vertical Chract.'!E11)/('Vertical Chract.'!A7-'Vertical Chract.'!A11) -> -0.0013 | N6: =M6*180/PI() -> -0.074484513
A7: Chord | B7: 6 | C7: 6
A8: Thickness | B8: =B7*B3 -> 0.54 | C8: =C7*B3 -> 0.54 | F8: Aspect Ratio | G8: xac (%) | H8: Lift Cruise Desired V (lb)
E9: 2D | F9: =E3^2/I2 -> 170.40384 | G9: =((-M6/H6)+0.25)*100 -> 26.221231 | H9: =0.5*'Vertical Chract.'!$B$9*$I$2*$B$4*$E$2^2 -> 0
B10: deg | C10: rad | E10: 3D | H10: =0.5*'Vertical Chract.'!$J$9*$I$2*$B$4*$E$2^2 -> 0
A11: Sweep Angle 0.5c | B11: 0 | C11: =B11*PI()/180 -> 0
A12: Sweep Angle LE | B12: 0 | C12: =B12*PI()/180 -> 0

Sheet Vertical Chract.
O1: t/w | P1: T/W
A2: alpha | B2: Cl | C2: Cd | D2: Cdp | E2: Cm | F2: Top_Xtr | G2: Bot_Xtr | I2: Linealized Cl | J2: CL | K2: CD | L2: CM | M2: l/d | N2: L/D | O2: 1/(l/d) | P2: 1/(L/D)
A3: ------ | B3: -------- | C3: --------- | D3: --------- | E3: -------- | F3: -------- | G3: -------- | I3: -------- | J3: -------- | K3: -------- | L3: -------- | M3: -------- | N3: -------- | O3: -------- | P3: -------- | S3: cl | T3: cl2/piar | U3: cd
A4: 10 | B4: 0.8181 | C4: 0.04214 | D4: 0.0387 | E4: 0.0275 | F4: 0.0266 | G4: 1 | I4: ='Vertical Info.'!$H$6*('Vertical Chract.'!A4-'Vertical Chract.'!$A$9) -> 1.0645 | J4: ='Vertical Info.'!$J$6*('Vertical Chract.'!A4-'Vertical Chract.'!$A$9) -> 1.0524412 | M4: =B4/C4 -> 19.413859 | N4: =J4/K4 -> #DIV/0! | O4: =1/M4 -> 0.051509595 | P4: =1/N4 -> #DIV/0! | S4: =0.1035*((A4-((57.3*J4)/(PI()*3.6)))-(-4.313)) -> 0.92952085 | T4: =J4^2/(PI()*'Vertical Info.'!$F$9*'Vertical Info.'!$E$6) -> -0.00038903157 | V4: =T4+U4 -> -0.00038903157
A5: 8 | B5: 0.8053 | C5: 0.01292 | D5: 0.00659 | E5: 0.0117 | F5: 0.028 | G5: 1 | I5: ='Vertical Info.'!$H$6*('Vertical Chract.'!A5-'Vertical Chract.'!$A$9) -> 0.8516 | J5: ='Vertical Info.'!$J$6*('Vertical Chract.'!A5-'Vertical Chract.'!$A$9) -> 0.84195297 | M5: =B5/C5 -> 62.329721 | N5: =J5/K5 -> #DIV/0! | O5: =1/M5 -> 0.01604371 | P5: =1/N5 -> #DIV/0! | S5: =0.1035*((A5-((57.3*J5)/(PI()*3.6)))-(-4.313)) -> 0.83289578 | T5: =J5^2/(PI()*'Vertical Info.'!$F$9*'Vertical Info.'!$E$6) -> -0.00024898021 | V5: =T5+U5 -> -0.00024898021
A6: 6 | B6: 0.6387 | C6: 0.00451 | D6: -0.00261 | E6: 0.0035 | F6: 0.0452 | G6: 1 | I6: ='Vertical Info.'!$H$6*('Vertical Chract.'!A6-'Vertical Chract.'!$A$9) -> 0.6387 | J6: ='Vertical Info.'!$J$6*('Vertical Chract.'!A6-'Vertical Chract.'!$A$9) -> 0.63146473 | M6: =B6/C6 -> 141.61863 | N6: =J6/K6 -> #DIV/0! | O6: =1/M6 -> 0.0070612181 | P6: =1/N6 -> #DIV/0! | S6: =0.1035*((A6-((57.3*J6)/(PI()*3.6)))-(-4.313)) -> 0.73627071 | T6: =J6^2/(PI()*'Vertical Info.'!$F$9*'Vertical Info.'!$E$6) -> -0.00014005137 | V6: =T6+U6 -> -0.00014005137
A7: 4 | B7: 0.4709 | C7: 0.00145 | D7: -0.00493 | E7: -0.0052 | F7: 0.2318 | G7: 1 | I7: ='Vertical Info.'!$H$6*('Vertical Chract.'!A7-'Vertical Chract.'!$A$9) -> 0.4258 | J7: ='Vertical Info.'!$J$6*('Vertical Chract.'!A7-'Vertical Chract.'!$A$9) -> 0.42097648 | M7: =B7/C7 -> 324.75862 | N7: =J7/K7 -> #DIV/0! | O7: =1/M7 -> 0.00307921 | P7: =1/N7 -> #DIV/0! | S7: =0.1035*((A7-((57.3*J7)/(PI()*3.6)))-(-4.313)) -> 0.63964564 | T7: =J7^2/(PI()*'Vertical Info.'!$F$9*'Vertical Info.'!$E$6) -> -6.2245052e-05 | V7: =T7+U7 -> -6.2245052e-05
A8: 2 | B8: 0.2889 | C8: 0.00077 | D8: -0.00391 | E8: -0.0114 | F8: 0.6871 | G8: 1 | I8: ='Vertical Info.'!$H$6*('Vertical Chract.'!A8-'Vertical Chract.'!$A$9) -> 0.2129 | J8: ='Vertical Info.'!$J$6*('Vertical Chract.'!A8-'Vertical Chract.'!$A$9) -> 0.21048824 | M8: =B8/C8 -> 375.19481 | N8: =J8/K8 -> #DIV/0! | O8: =1/M8 -> 0.0026652821 | P8: =1/N8 -> #DIV/0! | S8: =0.1035*((A8-((57.3*J8)/(PI()*3.6)))-(-4.313)) -> 0.54302057 | T8: =J8^2/(PI()*'Vertical Info.'!$F$9*'Vertical Info.'!$E$6) -> -1.5561263e-05 | V8: =T8+U8 -> -1.5561263e-05
A9: 0 | B9: 0 | C9: 0.00075 | D9: -0.00327 | E9: 0 | F9: 0.9459 | G9: 0.9458 | I9: ='Vertical Info.'!$H$6*('Vertical Chract.'!A9-'Vertical Chract.'!$A$9) -> 0 | J9: ='Vertical Info.'!$J$6*('Vertical Chract.'!A9-'Vertical Chract.'!$A$9) -> 0 | K9: 0.0014 | M9: =B9/C9 -> 0 | N9: =J9/K9 -> 0 | O9: =1/M9 -> #DIV/0! | P9: =1/N9 -> #DIV/0! | S9: =0.1035*((A9-((57.3*J9)/(PI()*3.6)))-(-4.313)) -> 0.4463955 | T9: =J9^2/(PI()*'Vertical Info.'!$F$9*'Vertical Info.'!$E$6) -> 0 | U9: 0.0014 | V9: =T9+U9 -> 0.0014
A10: -2 | B10: -0.2889 | C10: 0.00079 | D10: -0.00389 | E10: 0.0115 | F10: 1 | G10: 0.6876 | I10: ='Vertical Info.'!$H$6*('Vertical Chract.'!A10-'Vertical Chract.'!$A$9) -> -0.2129 | J10: ='Vertical Info.'!$J$6*('Vertical Chract.'!A10-'Vertical Chract.'!$A$9) -> -0.21048824 | M10: =B10/C10 -> -365.6962 | N10: =J10/K10 -> #DIV/0! | O10: =1/M10 -> -0.0027345102 | P10: =1/N10 -> #DIV/0! | S10: =0.1035*((A10-((57.3*J10)/(PI()*3.6)))-(-4.313)) -> 0.34977043 | T10: =J10^2/(PI()*'Vertical Info.'!$F$9*'Vertical Info.'!$E$6) -> -1.5561263e-05 | V10: =T10+U10 -> -1.5561263e-05
A11: -4 | B11: -0.4711 | C11: 0.0015 | D11: -0.00488 | E11: 0.0052 | F11: 1 | G11: 0.2322 | I11: ='Vertical Info.'!$H$6*('Vertical Chract.'!A11-'Vertical Chract.'!$A$9) -> -0.4258 | J11: ='Vertical Info.'!$J$6*('Vertical Chract.'!A11-'Vertical Chract.'!$A$9) -> -0.42097648 | M11: =B11/C11 -> -314.06667 | N11: =J11/K11 -> #DIV/0! | O11: =1/M11 -> -0.0031840374 | P11: =1/N11 -> #DIV/0! | S11: =0.1035*((A11-((57.3*J11)/(PI()*3.6)))-(-4.313)) -> 0.25314536 | T11: =J11^2/(PI()*'Vertical Info.'!$F$9*'Vertical Info.'!$E$6) -> -6.2245052e-05 | V11: =T11+U11 -> -6.2245052e-05
A12: -6 | B12: -0.6389 | C12: 0.0046 | D12: -0.00252 | E12: -0.0034 | F12: 1 | G12: 0.0453 | I12: ='Vertical Info.'!$H$6*('Vertical Chract.'!A12-'Vertical Chract.'!$A$9) -> -0.6387 | J12: ='Vertical Info.'!$J$6*('Vertical Chract.'!A12-'Vertical Chract.'!$A$9) -> -0.63146473 | M12: =B12/C12 -> -138.8913 | N12: =J12/K12 -> #DIV/0! | O12: =1/M12 -> -0.0071998748 | P12: =1/N12 -> #DIV/0! | S12: =0.1035*((A12-((57.3*J12)/(PI()*3.6)))-(-4.313)) -> 0.15652029 | T12: =J12^2/(PI()*'Vertical Info.'!$F$9*'Vertical Info.'!$E$6) -> -0.00014005137 | V12: =T12+U12 -> -0.00014005137
A13: -8 | B13: -0.8056 | C13: 0.01301 | D13: 0.00668 | E13: -0.0117 | F13: 1 | G13: 0.028 | I13: ='Vertical Info.'!$H$6*('Vertical Chract.'!A13-'Vertical Chract.'!$A$9) -> -0.8516 | J13: ='Vertical Info.'!$J$6*('Vertical Chract.'!A13-'Vertical Chract.'!$A$9) -> -0.84195297 | M13: =B13/C13 -> -61.921599 | N13: =J13/K13 -> #DIV/0! | O13: =1/M13 -> -0.016149454 | P13: =1/N13 -> #DIV/0! | S13: =0.1035*((A13-((57.3*J13)/(PI()*3.6)))-(-4.313)) -> 0.059895218 | T13: =J13^2/(PI()*'Vertical Info.'!$F$9*'Vertical Info.'!$E$6) -> -0.00024898021 | V13: =T13+U13 -> -0.00024898021
A14: -10 | B14: -0.8798 | C14: 0.05453 | D14: 0.05102 | E14: -0.0214 | F14: 1 | G14: 0.0264 | I14: ='Vertical Info.'!$H$6*('Vertical Chract.'!A14-'Vertical Chract.'!$A$9) -> -1.0645 | J14: ='Vertical Info.'!$J$6*('Vertical Chract.'!A14-'Vertical Chract.'!$A$9) -> -1.0524412 | M14: =B14/C14 -> -16.134238 | N14: =J14/K14 -> #DIV/0! | O14: =1/M14 -> -0.061979995 | P14: =1/N14 -> #DIV/0! | S14: =0.1035*((A14-((57.3*J14)/(PI()*3.6)))-(-4.313)) -> -0.036729853 | T14: =J14^2/(PI()*'Vertical Info.'!$F$9*'Vertical Info.'!$E$6) -> -0.00038903157 | V14: =T14+U14 -> -0.00038903157

Sheet Take Off and Turn
A1: WLO | B1: 7.5 | D1: V (ft/s) | E1: L | F1: n | G1: phi (deg) | H1: Rb4 | I1: Raft | J1: R2 | L1: T | M1: SLO (ft) | N1: SL (ft)
A2: WL | B2: 5.5 | D2: 70 | E2: 5.7658569 | F2: =E2/$B$1 -> 0.76878093 | G2: =ACOS(1/F2)*180/PI() -> #NUM! | H2: =(1/(0.5*$B$5*$B$4*$B$3))*($B$1/($B$6))*(F2/SQRT((F2^2)-1)) -> #NUM! | I2: =(1/(0.5*$B$5*$B$4*$B$3))*($B$2/($B$6))*(F2/SQRT((F2^2)-1)) -> #NUM! | J2: =(D2^2)/($B$5*SQRT(4^2-1)) -> 39.322887 | L2: 4 | M2: =(1.44*$B$1^2)/($B$3*$B$4*$B$5*$B$6*(L2-($B$8-0.025*($B$1-$B$7)))) -> 52.651255 | N2: =(1.69*$B$2^2)/($B$3*$B$4*$B$5*$B$6*($B$8+0.4*($B$2-$B$9))) -> 85.338214
A3: CL | B3: 1 | D3: 75 | E3: 6.6189684 | F3: =E3/$B$1 -> 0.88252912 | G3: =ACOS(1/F3)*180/PI() -> #NUM! | H3: =(1/(0.5*$B$5*$B$4*$B$3))*($B$1/($B$6))*(F3/SQRT((F3^2)-1)) -> #NUM! | I3: =(1/(0.5*$B$5*$B$4*$B$3))*($B$2/($B$6))*(F3/SQRT((F3^2)-1)) -> #NUM! | J3: =(D3^2)/($B$5*SQRT(4^2-1)) -> 45.141069 | L3: 4.5 | M3: =(1.44*$B$1^2)/($B$3*$B$4*$B$5*$B$6*(L3-($B$8-0.025*($B$1-$B$7)))) -> 46.855955
A4: roh | B4: 0.00228782 | D4: 80 | E4: 7.5309152 | F4: =E4/$B$1 -> 1.004122 | G4: =ACOS(1/F4)*180/PI() -> 5.19336 | H4: =(1/(0.5*$B$5*$B$4*$B$3))*($B$1/($B$6))*(F4/SQRT((F4^2)-1)) -> 435.45457 | I4: =(1/(0.5*$B$5*$B$4*$B$3))*($B$2/($B$6))*(F4/SQRT((F4^2)-1)) -> 319.33335 | J4: =(D4^2)/($B$5*SQRT(4^2-1)) -> 51.360505 | L4: 5 | M4: =(1.44*$B$1^2)/($B$3*$B$4*$B$5*$B$6*(L4-($B$8-0.025*($B$1-$B$7)))) -> 42.209927
A5: g | B5: 32.174 | D5: 85 | E5: 8.5016972 | F5: =E5/$B$1 -> 1.1335596 | G5: =ACOS(1/F5)*180/PI() -> 28.093926 | H5: =(1/(0.5*$B$5*$B$4*$B$3))*($B$1/($B$6))*(F5/SQRT((F5^2)-1)) -> 83.700524 | I5: =(1/(0.5*$B$5*$B$4*$B$3))*($B$2/($B$6))*(F5/SQRT((F5^2)-1)) -> 61.380385 | J5: =(D5^2)/($B$5*SQRT(4^2-1)) -> 57.981195 | L5: 5.5 | M5: =(1.44*$B$1^2)/($B$3*$B$4*$B$5*$B$6*(L5-($B$8-0.025*($B$1-$B$7)))) -> 38.402141
A6: S (ft^2) | B6: 5.17 | D6: 90 | E6: 9.5313145 | F6: =E6/$B$1 -> 1.2708419 | G6: =ACOS(1/F6)*180/PI() -> 38.105117 | H6: =(1/(0.5*$B$5*$B$4*$B$3))*($B$1/($B$6))*(F6/SQRT((F6^2)-1)) -> 63.872503 | I6: =(1/(0.5*$B$5*$B$4*$B$3))*($B$2/($B$6))*(F6/SQRT((F6^2)-1)) -> 46.839835 | J6: =(D6^2)/($B$5*SQRT(4^2-1)) -> 65.003139 | L6: 6 | M6: =(1.44*$B$1^2)/($B$3*$B$4*$B$5*$B$6*(L6-($B$8-0.025*($B$1-$B$7)))) -> 35.224514
A7: L @ 0.7VLO | B7: 1.55 | D7: 95 | E7: 10.619767 | F7: =E7/$B$1 -> 1.415969 | G7: =ACOS(1/F7)*180/PI() -> 45.070986 | H7: =(1/(0.5*$B$5*$B$4*$B$3))*($B$1/($B$6))*(F7/SQRT((F7^2)-1)) -> 55.673869 | I7: =(1/(0.5*$B$5*$B$4*$B$3))*($B$2/($B$6))*(F7/SQRT((F7^2)-1)) -> 40.827504 | J7: =(D7^2)/($B$5*SQRT(4^2-1)) -> 72.426337 | L7: 6.5 | M7: =(1.44*$B$1^2)/($B$3*$B$4*$B$5*$B$6*(L7-($B$8-0.025*($B$1-$B$7)))) -> 32.532571
A8: D @ 0.7VLO | B8: 0.106168 | D8: 100 | E8: 11.767055 | F8: =E8/$B$1 -> 1.5689407 | G8: =ACOS(1/F8)*180/PI() -> 50.403811 | H8: =(1/(0.5*$B$5*$B$4*$B$3))*($B$1/($B$6))*(F8/SQRT((F8^2)-1)) -> 51.152846 | I8: =(1/(0.5*$B$5*$B$4*$B$3))*($B$2/($B$6))*(F8/SQRT((F8^2)-1)) -> 37.512087 | J8: =(D8^2)/($B$5*SQRT(4^2-1)) -> 80.250789 | L8: 7 | M8: =(1.44*$B$1^2)/($B$3*$B$4*$B$5*$B$6*(L8-($B$8-0.025*($B$1-$B$7)))) -> 30.222867
A9: L @ 0.7VT | B9: 1.83 | D9: 105 | E9: 12.973178 | F9: =E9/$B$1 -> 1.7297571 | G9: =ACOS(1/F9)*180/PI() -> 54.681869 | H9: =(1/(0.5*$B$5*$B$4*$B$3))*($B$1/($B$6))*(F9/SQRT((F9^2)-1)) -> 48.306744 | I9: =(1/(0.5*$B$5*$B$4*$B$3))*($B$2/($B$6))*(F9/SQRT((F9^2)-1)) -> 35.424945 | J9: =(D9^2)/($B$5*SQRT(4^2-1)) -> 88.476495 | L9: 7.5 | M9: =(1.44*$B$1^2)/($B$3*$B$4*$B$5*$B$6*(L9-($B$8-0.025*($B$1-$B$7)))) -> 28.219384
D10: 110 | E10: 14.238137 | F10: =E10/$B$1 -> 1.8984182 | G10: =ACOS(1/F10)*180/PI() -> 58.213581 | H10: =(1/(0.5*$B$5*$B$4*$B$3))*($B$1/($B$6))*(F10/SQRT((F10^2)-1)) -> 46.37094 | I10: =(1/(0.5*$B$5*$B$4*$B$3))*($B$2/($B$6))*(F10/SQRT((F10^2)-1)) -> 34.005356 | J10: =(D10^2)/($B$5*SQRT(4^2-1)) -> 97.103455 | L10: 8 | M10: =(1.44*$B$1^2)/($B$3*$B$4*$B$5*$B$6*(L10-($B$8-0.025*($B$1-$B$7)))) -> 26.46501
D11: 115 | E11: 15.56193 | F11: =E11/$B$1 -> 2.074924 | G11: =ACOS(1/F11)*180/PI() -> 61.187466 | H11: =(1/(0.5*$B$5*$B$4*$B$3))*($B$1/($B$6))*(F11/SQRT((F11^2)-1)) -> 44.985228 | I11: =(1/(0.5*$B$5*$B$4*$B$3))*($B$2/($B$6))*(F11/SQRT((F11^2)-1)) -> 32.989167 | J11: =(D11^2)/($B$5*SQRT(4^2-1)) -> 106.13167 | L11: 8.5 | M11: =(1.44*$B$1^2)/($B$3*$B$4*$B$5*$B$6*(L11-($B$8-0.025*($B$1-$B$7)))) -> 24.916005
D12: 120 | E12: 16.944559 | F12: =E12/$B$1 -> 2.2592746 | G12: =ACOS(1/F12)*180/PI() -> 63.728836 | H12: =(1/(0.5*$B$5*$B$4*$B$3))*($B$1/($B$6))*(F12/SQRT((F12^2)-1)) -> 43.956401 | I12: =(1/(0.5*$B$5*$B$4*$B$3))*($B$2/($B$6))*(F12/SQRT((F12^2)-1)) -> 32.234694 | J12: =(D12^2)/($B$5*SQRT(4^2-1)) -> 115.56114 | L12: 9 | M12: =(1.44*$B$1^2)/($B$3*$B$4*$B$5*$B$6*(L12-($B$8-0.025*($B$1-$B$7)))) -> 23.538301
F13: 4 | G13: =ACOS(1/F13)*180/PI() -> 75.522488 | H13: =(1/(0.5*$B$5*$B$4*$B$3))*($B$1/($B$6))*(F13/SQRT((F13^2)-1)) -> 40.708788 | I13: =(1/(0.5*$B$5*$B$4*$B$3))*($B$2/($B$6))*(F13/SQRT((F13^2)-1)) -> 29.853111 | L13: 9.5 | M13: =(1.44*$B$1^2)/($B$3*$B$4*$B$5*$B$6*(L13-($B$8-0.025*($B$1-$B$7)))) -> 22.304971
L14: 10 | M14: =(1.44*$B$1^2)/($B$3*$B$4*$B$5*$B$6*(L14-($B$8-0.025*($B$1-$B$7)))) -> 21.194451

Sheet Xfoil vs Exp.
A1: Experimental (NACA document) | J1: XFOIL
A2: alpha | B2: CL | D2: alpha | E2: CM | G2: CL | H2: CD | J2: alpha | K2: CL | L2: CD | M2: CM | O2: alpha | P2: CL
A3: 20.026599 | B3: 1.2849179 | D3: 20.441367 | E3: -0.065861483 | G3: 1.3961865 | H3: 0.019911056 | J3: 20 | K3: 1.4515 | L3: 0.11532 | M3: -0.0377 | O3: 14 | P3: 1.5377256
A4: 18.339631 | B4: 1.3504009 | D4: 18.490331 | E4: -0.067260816 | G4: 1.2929018 | H4: 0.013379845 | J4: 18 | K4: 1.4771 | L4: 0.08714 | M4: -0.0325 | O4: 12 | P4: 1.4500256
A5: 16.164317 | B5: 1.3934322 | D5: 16.273239 | E5: -0.062129928 | G5: 1.1582635 | H5: 0.010282185 | J5: 16 | K5: 1.5207 | L5: 0.05858 | M5: -0.0325 | O5: 10 | P5: 1.3623256
A6: 14.210978 | B6: 1.4214962 | D6: 14.322203 | E6: -0.058398527 | G6: 0.98858219 | H6: 0.0088453123 | J6: 14 | K6: 1.5347 | L6: 0.03697 | M6: -0.0394 | O6: 8 | P6: 1.2746256
A7: 12.346414 | B7: 1.3822069 | D7: 12.326824 | E7: -0.058864971 | G7: 0.79123543 | H7: 0.0078936254 | J7: 12 | K7: 1.4914 | L7: 0.02488 | M7: -0.0524 | O7: 6 | P7: 1.0675942
A8: 10.259905 | B8: 1.2849179 | D8: 10.154075 | E8: -0.063062817 | G8: 0.61233207 | H8: 0.0075577335 | J8: 10 | K8: 1.3967 | L8: 0.01896 | M8: -0.0675 | O8: 4 | P8: 0.8605628
A9: 8.1289859 | B9: 1.1464686 | D9: 8.1586961 | E9: -0.070992217 | G9: 0.37256467 | H9: 0.0075204114 | J9: 8 | K9: 1.2713 | L9: 0.0162 | M9: -0.0831 | O9: 2 | P9: 0.6535314
A10: 6.086857 | B10: 0.98182628 | D10: 6.2076601 | E10: -0.078455174 | G10: 0.20841654 | H10: 0.0075390725 | J10: 6 | K10: 1.1019 | L10: 0.01429 | M10: -0.0925 | O10: 0 | P10: 0.4465
A11: 4.0891085 | B11: 0.8022161 | D11: 4.2122814 | E11: -0.08125384 | G11: -0.01659565 | H11: 0.0080615684 | J11: 4 | K11: 0.9295 | L11: 0.01281 | M11: -0.1021 | O11: -2 | P11: 0.2394686
A12: 1.958204 | B12: 0.6076381 | D12: 2.3055736 | E12: -0.087317463 | G12: -0.18996579 | H12: 0.0083041553 | J12: 2 | K12: 0.6802 | L12: 0.01151 | M12: -0.0954 | O12: -4 | P12: 0.032437199
A13: 0.09364071 | B13: 0.40183547 | D13: -0.044532298 | E13: -0.088250352 | G13: -0.4371102 | H13: 0.0092185263 | J13: 0 | K13: 0.4492 | L13: 0.01087 | M13: -0.0966 | O13: -6 | P13: -0.1745942
A14: -2.2592391 | B14: 0.22035431 | D14: -2.0842537 | E14: -0.088250352 | G14: -0.62154676 | H14: 0.010543433 | J14: -2 | K14: 0.2474 | L14: 0.01187 | M14: -0.1015 | O14: -8 | P14: -0.3816256
A15: -4.301368 | B15: 0.012680086 | D15: -4.1683179 | E15: -0.088250352 | G15: -0.83364873 | H15: 0.012894671 | J15: -4 | K15: 0.0352 | L15: 0.01301 | M15: -0.1045 | O15: -10 | P15: -0.588657
A16: -6.343497 | B16: -0.19125219 | D16: -6.1636966 | E16: -0.091048864 | J16: -6 | K16: -0.1792 | L16: 0.01508 | M16: -0.1073 | O16: -12 | P16: -0.7956884
A17: -8.2080603 | B17: -0.39331348 | D17: -7.981719 | E17: -0.092448197 | J17: -8 | K17: -0.3912 | L17: 0.01864 | M17: -0.1098
A18: -10.383374 | B18: -0.61408455 | J18: -10 | K18: -0.6338 | L18: 0.02381 | M18: -0.1045
A19: -12.381108 | B19: -0.83111306 | J19: -12 | K19: -0.8743 | L19: 0.03134 | M19: -0.0942
A20: -14.378842 | B20: -0.86479004 | J20: -13 | K20: -0.3141 | L20: 0.1356 | M20: -0.0465
J21: -16 | K21: -0.3344 | L21: 0.16729 | M21: -0.0448
J22: -18 | K22: -0.3775 | L22: 0.19278 | M22: -0.0324

Sheet Optional 1
A1: Airfoil: | B1: NACA4418 | D1: Desired Weight (lb): | E1: 1 | H1: in2 | I1: ft2 | K1: Taper Ratio | L1: Mean Aerodynamic Chord | M1: Y bar | V1: T/W
A2: Re #: | B2: 250000 | D2: Desired Vcruise (ft/s): | E2: 80 | G2: Surface Area | H2: 163.6 | I2: =H2/144 -> 1.1361111 | K2: =C7/B7 -> 0.38465 | L2: =(2/3)*B7*(1+K2+K2^2)/(1+K2) -> 17.709667 | M2: =(12*E3/6)*((1+2*K2)/(1+K2)) -> 2.5555917 | P2: alpha | Q2: Linealized Cl | R2: CL | S2: CD | T2: CM | U2: L/D | V2: 1/(L/D)
A3: t/c | B3: 0.18 | D3: Desired Wing Span (ft): | E3: 1 | P3: ------ | Q3: -------- | R3: -------- | S3: -------- | T3: -------- | U3: -------- | V3: --------
A4: Density (slug/ft3): | B4: 0.00228782 | G4: αCl=0 | H4: a0 (0-8) | J4: a (0-8) | M4: m0 | P4: 20
E5: e | G5: deg | H5: /deg | I5: /rad | J5: /deg | K5: /rad | M5: /deg | N5: /rad | P5: 18
B6: Root | C6: Tip | E6: =4.61*(1-0.045*F11^(0.68))*(COS(C12))^0.15-3.1 -> 1.303917 | G6: =('Wing Chract. (Ref)'!A16)-(('Wing Chract. (Ref)'!B16)/(('Wing Chract. (Ref)'!B16-'Wing Chract. (Ref)'!B17)/('Wing Chract. (Ref)'!A16-'Wing Chract. (Ref)'!A17))) -> -4.3133554 | H6: =('Wing Chract. (Ref)'!B14-0)/(0-'Wing Info. (Ref)'!G6) -> 0.1035157 | I6: =H6*180/PI() -> 5.9310127 | J6: =K6*PI()/180 -> 0.021124171 | K6: =I6*COS(C11)/(SQRT(1+(I6*COS(C11)/(PI()*F11))^2)+(I6*COS(C11)/(PI()*F11))) -> 1.2103258 | M6: =('Wing Chract. (Ref)'!E12-'Wing Chract. (Ref)'!E17)/('Wing Chract. (Ref)'!A12-'Wing Chract. (Ref)'!A17) -> 0.00055 | N6: =M6*180/PI() -> 0.031512679 | P6: 16 | X6: cl | Y6: cl2/piar | Z6: cd
A7: Chord | B7: 24 | C7: 9.2316 | H7: =('Wing Chract. (Ref)'!B8-'Wing Chract. (Ref)'!B9)/('Wing Chract. (Ref)'!A8-'Wing Chract. (Ref)'!A9) -> 0.04385 | I7: =H7*180/PI() -> 2.5124199 | J7: =K7*PI()/180 -> 0.015318859 | K7: =I7*COS(C11)/(SQRT(1+(I7*COS(C11)/(PI()*F11))^2)+(I7*COS(C11)/(PI()*F11))) -> 0.87770596 | P7: 14 | Q7: =$H$7*(P7-$P$10)+$Q$27 -> 1.5377256 | R7: =$J$7*(P7-$P$10)+$R$27 -> 0.35202257 | U7: =R7/S7 -> #DIV/0! | V7: =1/U7 -> #DIV/0! | X7: =0.1035*((P7-((57.3*R7)/(PI()*3.6)))-(-4.313)) -> 1.7108034 | Y7: =R7^2/(PI()*$E$6*$F$11) -> 0.034368614 | AA7: =Y7+Z7 -> 0.034368614
